Workbook

Sheet 1月
A2: 2026 | B2: 年 | C2: 1 | D2: 月度出勤簿 | J2: 氏 名 | K2: 盛田 裕一
A6: 日付 | D6: 勤務時間 | G6: 通常残業 | H6: 深夜残業 | I6: 早朝残業 | J6: 遅刻・早退 | K6: 理由
A7: =DATE($A$2,$C$2,1) -> 46023 | B7: =IF(A7="","","日") | C7: =IF(A7="","","("&CHOOSE(WEEKDAY(A7,2),"月","火","水","木","金","土","日")&"）") -> (木） | E7: ～ | K7: =IF($A7="","",IFERROR(VLOOKUP($A7,祝日リスト!$A$2:$C$40,3,0),"")) -> 元日 | N7: =IF(NOT(ISNUMBER($D7)),"",IF($D7<1,$D7,(INT($D7/100)*60+MOD($D7,100))/1440)) | O7: =IF(NOT(ISNUMBER($F7)),"",IF($F7<1,$F7,(INT($F7/100)*60+MOD($F7,100))/1440)) | P7: =IF(NOT(ISNUMBER($G7)),"",IF($G7<1,$G7,(INT($G7/100)*60+MOD($G7,100))/1440)) | Q7: =IF(NOT(ISNUMBER($H7)),"",IF($H7<1,$H7,(INT($H7/100)*60+MOD($H7,100))/1440)) | R7: =IF(NOT(ISNUMBER($I7)),"",IF($I7<1,$I7,(INT($I7/100)*60+MOD($I7,100))/1440)) | S7: =IF(NOT(ISNUMBER($J7)),"",IF($J7<1,$J7,(INT($J7/100)*60+MOD($J7,100))/1440)) | T7: =IF(OR($N7="",$O7=""),"",MOD($O7-$N7,1)) | U7: =IF($A7="","",IF($K7<>"","祝",IF(WEEKDAY($A7,2)=6,"土",IF(WEEKDAY($A7,2)=7,"日","平"))))
A8: =IF(A7="","",IF(MONTH(A7+1)=$C$2,A7+1,"")) -> 46024 | B8: =IF(A8="","","日") | C8: =IF(A8="","","("&CHOOSE(WEEKDAY(A8,2),"月","火","水","木","金","土","日")&"）") -> (金） | E8: ～ | K8: =IF($A8="","",IFERROR(VLOOKUP($A8,祝日リスト!$A$2:$C$40,3,0),"")) | N8: =IF(NOT(ISNUMBER($D8)),"",IF($D8<1,$D8,(INT($D8/100)*60+MOD($D8,100))/1440)) | O8: =IF(NOT(ISNUMBER($F8)),"",IF($F8<1,$F8,(INT($F8/100)*60+MOD($F8,100))/1440)) | P8: =IF(NOT(ISNUMBER($G8)),"",IF($G8<1,$G8,(INT($G8/100)*60+MOD($G8,100))/1440)) | Q8: =IF(NOT(ISNUMBER($H8)),"",IF($H8<1,$H8,(INT($H8/100)*60+MOD($H8,100))/1440)) | R8: =IF(NOT(ISNUMBER($I8)),"",IF($I8<1,$I8,(INT($I8/100)*60+MOD($I8,100))/1440)) | S8: =IF(NOT(ISNUMBER($J8)),"",IF($J8<1,$J8,(INT($J8/100)*60+MOD($J8,100))/1440)) | T8: =IF(OR($N8="",$O8=""),"",MOD($O8-$N8,1)) | U8: =IF($A8="","",IF($K8<>"","祝",IF(WEEKDAY($A8,2)=6,"土",IF(WEEKDAY($A8,2)=7,"日","平"))))
A9: =IF(A8="","",IF(MONTH(A8+1)=$C$2,A8+1,"")) -> 46025 | B9: =IF(A9="","","日") | C9: =IF(A9="","","("&CHOOSE(WEEKDAY(A9,2),"月","火","水","木","金","土","日")&"）") -> (土） | E9: ～ | K9: =IF($A9="","",IFERROR(VLOOKUP($A9,祝日リスト!$A$2:$C$40,3,0),"")) | N9: =IF(NOT(ISNUMBER($D9)),"",IF($D9<1,$D9,(INT($D9/100)*60+MOD($D9,100))/1440)) | O9: =IF(NOT(ISNUMBER($F9)),"",IF($F9<1,$F9,(INT($F9/100)*60+MOD($F9,100))/1440)) | P9: =IF(NOT(ISNUMBER($G9)),"",IF($G9<1,$G9,(INT($G9/100)*60+MOD($G9,100))/1440)) | Q9: =IF(NOT(ISNUMBER($H9)),"",IF($H9<1,$H9,(INT($H9/100)*60+MOD($H9,100))/1440)) | R9: =IF(NOT(ISNUMBER($I9)),"",IF($I9<1,$I9,(INT($I9/100)*60+MOD($I9,100))/1440)) | S9: =IF(NOT(ISNUMBER($J9)),"",IF($J9<1,$J9,(INT($J9/100)*60+MOD($J9,100))/1440)) | T9: =IF(OR($N9="",$O9=""),"",MOD($O9-$N9,1)) | U9: =IF($A9="","",IF($K9<>"","祝",IF(WEEKDAY($A9,2)=6,"土",IF(WEEKDAY($A9,2)=7,"日","平"))))
A10: =IF(A9="","",IF(MONTH(A9+1)=$C$2,A9+1,"")) -> 46026 | B10: =IF(A10="","","日") | C10: =IF(A10="","","("&CHOOSE(WEEKDAY(A10,2),"月","火","水","木","金","土","日")&"）") -> (日） | E10: ～ | K10: =IF($A10="","",IFERROR(VLOOKUP($A10,祝日リスト!$A$2:$C$40,3,0),"")) | N10: =IF(NOT(ISNUMBER($D10)),"",IF($D10<1,$D10,(INT($D10/100)*60+MOD($D10,100))/1440)) | O10: =IF(NOT(ISNUMBER($F10)),"",IF($F10<1,$F10,(INT($F10/100)*60+MOD($F10,100))/1440)) | P10: =IF(NOT(ISNUMBER($G10)),"",IF($G10<1,$G10,(INT($G10/100)*60+MOD($G10,100))/1440)) | Q10: =IF(NOT(ISNUMBER($H10)),"",IF($H10<1,$H10,(INT($H10/100)*60+MOD($H10,100))/1440)) | R10: =IF(NOT(ISNUMBER($I10)),"",IF($I10<1,$I10,(INT($I10/100)*60+MOD($I10,100))/1440)) | S10: =IF(NOT(ISNUMBER($J10)),"",IF($J10<1,$J10,(INT($J10/100)*60+MOD($J10,100))/1440)) | T10: =IF(OR($N10="",$O10=""),"",MOD($O10-$N10,1)) | U10: =IF($A10="","",IF($K10<>"","祝",IF(WEEKDAY($A10,2)=6,"土",IF(WEEKDAY($A10,2)=7,"日","平"))))
A11: =IF(A10="","",IF(MONTH(A10+1)=$C$2,A10+1,"")) -> 46027 | B11: =IF(A11="","","日") | C11: =IF(A11="","","("&CHOOSE(WEEKDAY(A11,2),"月","火","水","木","金","土","日")&"）") -> (月） | E11: ～ | K11: =IF($A11="","",IFERROR(VLOOKUP($A11,祝日リスト!$A$2:$C$40,3,0),"")) | N11: =IF(NOT(ISNUMBER($D11)),"",IF($D11<1,$D11,(INT($D11/100)*60+MOD($D11,100))/1440)) | O11: =IF(NOT(ISNUMBER($F11)),"",IF($F11<1,$F11,(INT($F11/100)*60+MOD($F11,100))/1440)) | P11: =IF(NOT(ISNUMBER($G11)),"",IF($G11<1,$G11,(INT($G11/100)*60+MOD($G11,100))/1440)) | Q11: =IF(NOT(ISNUMBER($H11)),"",IF($H11<1,$H11,(INT($H11/100)*60+MOD($H11,100))/1440)) | R11: =IF(NOT(ISNUMBER($I11)),"",IF($I11<1,$I11,(INT($I11/100)*60+MOD($I11,100))/1440)) | S11: =IF(NOT(ISNUMBER($J11)),"",IF($J11<1,$J11,(INT($J11/100)*60+MOD($J11,100))/1440)) | T11: =IF(OR($N11="",$O11=""),"",MOD($O11-$N11,1)) | U11: =IF($A11="","",IF($K11<>"","祝",IF(WEEKDAY($A11,2)=6,"土",IF(WEEKDAY($A11,2)=7,"日","平"))))
A12: =IF(A11="","",IF(MONTH(A11+1)=$C$2,A11+1,"")) -> 46028 | B12: =IF(A12="","","日") | C12: =IF(A12="","","("&CHOOSE(WEEKDAY(A12,2),"月","火","水","木","金","土","日")&"）") -> (火） | E12: ～ | K12: =IF($A12="","",IFERROR(VLOOKUP($A12,祝日リスト!$A$2:$C$40,3,0),"")) | N12: =IF(NOT(ISNUMBER($D12)),"",IF($D12<1,$D12,(INT($D12/100)*60+MOD($D12,100))/1440)) | O12: =IF(NOT(ISNUMBER($F12)),"",IF($F12<1,$F12,(INT($F12/100)*60+MOD($F12,100))/1440)) | P12: =IF(NOT(ISNUMBER($G12)),"",IF($G12<1,$G12,(INT($G12/100)*60+MOD($G12,100))/1440)) | Q12: =IF(NOT(ISNUMBER($H12)),"",IF($H12<1,$H12,(INT($H12/100)*60+MOD($H12,100))/1440)) | R12: =IF(NOT(ISNUMBER($I12)),"",IF($I12<1,$I12,(INT($I12/100)*60+MOD($I12,100))/1440)) | S12: =IF(NOT(ISNUMBER($J12)),"",IF($J12<1,$J12,(INT($J12/100)*60+MOD($J12,100))/1440)) | T12: =IF(OR($N12="",$O12=""),"",MOD($O12-$N12,1)) | U12: =IF($A12="","",IF($K12<>"","祝",IF(WEEKDAY($A12,2)=6,"土",IF(WEEKDAY($A12,2)=7,"日","平"))))
A13: =IF(A12="","",IF(MONTH(A12+1)=$C$2,A12+1,"")) -> 46029 | B13: =IF(A13="","","日") | C13: =IF(A13="","","("&CHOOSE(WEEKDAY(A13,2),"月","火","水","木","金","土","日")&"）") -> (水） | E13: ～ | K13: =IF($A13="","",IFERROR(VLOOKUP($A13,祝日リスト!$A$2:$C$40,3,0),"")) | N13: =IF(NOT(ISNUMBER($D13)),"",IF($D13<1,$D13,(INT($D13/100)*60+MOD($D13,100))/1440)) | O13: =IF(NOT(ISNUMBER($F13)),"",IF($F13<1,$F13,(INT($F13/100)*60+MOD($F13,100))/1440)) | P13: =IF(NOT(ISNUMBER($G13)),"",IF($G13<1,$G13,(INT($G13/100)*60+MOD($G13,100))/1440)) | Q13: =IF(NOT(ISNUMBER($H13)),"",IF($H13<1,$H13,(INT($H13/100)*60+MOD($H13,100))/1440)) | R13: =IF(NOT(ISNUMBER($I13)),"",IF($I13<1,$I13,(INT($I13/100)*60+MOD($I13,100))/1440)) | S13: =IF(NOT(ISNUMBER($J13)),"",IF($J13<1,$J13,(INT($J13/100)*60+MOD($J13,100))/1440)) | T13: =IF(OR($N13="",$O13=""),"",MOD($O13-$N13,1)) | U13: =IF($A13="","",IF($K13<>"","祝",IF(WEEKDAY($A13,2)=6,"土",IF(WEEKDAY($A13,2)=7,"日","平"))))
A14: =IF(A13="","",IF(MONTH(A13+1)=$C$2,A13+1,"")) -> 46030 | B14: =IF(A14="","","日") | C14: =IF(A14="","","("&CHOOSE(WEEKDAY(A14,2),"月","火","水","木","金","土","日")&"）") -> (木） | E14: ～ | K14: =IF($A14="","",IFERROR(VLOOKUP($A14,祝日リスト!$A$2:$C$40,3,0),"")) | N14: =IF(NOT(ISNUMBER($D14)),"",IF($D14<1,$D14,(INT($D14/100)*60+MOD($D14,100))/1440)) | O14: =IF(NOT(ISNUMBER($F14)),"",IF($F14<1,$F14,(INT($F14/100)*60+MOD($F14,100))/1440)) | P14: =IF(NOT(ISNUMBER($G14)),"",IF($G14<1,$G14,(INT($G14/100)*60+MOD($G14,100))/1440)) | Q14: =IF(NOT(ISNUMBER($H14)),"",IF($H14<1,$H14,(INT($H14/100)*60+MOD($H14,100))/1440)) | R14: =IF(NOT(ISNUMBER($I14)),"",IF($I14<1,$I14,(INT($I14/100)*60+MOD($I14,100))/1440)) | S14: =IF(NOT(ISNUMBER($J14)),"",IF($J14<1,$J14,(INT($J14/100)*60+MOD($J14,100))/1440)) | T14: =IF(OR($N14="",$O14=""),"",MOD($O14-$N14,1)) | U14: =IF($A14="","",IF($K14<>"","祝",IF(WEEKDAY($A14,2)=6,"土",IF(WEEKDAY($A14,2)=7,"日","平"))))
A15: =IF(A14="","",IF(MONTH(A14+1)=$C$2,A14+1,"")) -> 46031 | B15: =IF(A15="","","日") | C15: =IF(A15="","","("&CHOOSE(WEEKDAY(A15,2),"月","火","水","木","金","土","日")&"）") -> (金） | E15: ～ | K15: =IF($A15="","",IFERROR(VLOOKUP($A15,祝日リスト!$A$2:$C$40,3,0),"")) | N15: =IF(NOT(ISNUMBER($D15)),"",IF($D15<1,$D15,(INT($D15/100)*60+MOD($D15,100))/1440)) | O15: =IF(NOT(ISNUMBER($F15)),"",IF($F15<1,$F15,(INT($F15/100)*60+MOD($F15,100))/1440)) | P15: =IF(NOT(ISNUMBER($G15)),"",IF($G15<1,$G15,(INT($G15/100)*60+MOD($G15,100))/1440)) | Q15: =IF(NOT(ISNUMBER($H15)),"",IF($H15<1,$H15,(INT($H15/100)*60+MOD($H15,100))/1440)) | R15: =IF(NOT(ISNUMBER($I15)),"",IF($I15<1,$I15,(INT($I15/100)*60+MOD($I15,100))/1440)) | S15: =IF(NOT(ISNUMBER($J15)),"",IF($J15<1,$J15,(INT($J15/100)*60+MOD($J15,100))/1440)) | T15: =IF(OR($N15="",$O15=""),"",MOD($O15-$N15,1)) | U15: =IF($A15="","",IF($K15<>"","祝",IF(WEEKDAY($A15,2)=6,"土",IF(WEEKDAY($A15,2)=7,"日","平"))))
A16: =IF(A15="","",IF(MONTH(A15+1)=$C$2,A15+1,"")) -> 46032 | B16: =IF(A16="","","日") | C16: =IF(A16="","","("&CHOOSE(WEEKDAY(A16,2),"月","火","水","木","金","土","日")&"）") -> (土） | E16: ～ | K16: =IF($A16="","",IFERROR(VLOOKUP($A16,祝日リスト!$A$2:$C$40,3,0),"")) | N16: =IF(NOT(ISNUMBER($D16)),"",IF($D16<1,$D16,(INT($D16/100)*60+MOD($D16,100))/1440)) | O16: =IF(NOT(ISNUMBER($F16)),"",IF($F16<1,$F16,(INT($F16/100)*60+MOD($F16,100))/1440)) | P16: =IF(NOT(ISNUMBER($G16)),"",IF($G16<1,$G16,(INT($G16/100)*60+MOD($G16,100))/1440)) | Q16: =IF(NOT(ISNUMBER($H16)),"",IF($H16<1,$H16,(INT($H16/100)*60+MOD($H16,100))/1440)) | R16: =IF(NOT(ISNUMBER($I16)),"",IF($I16<1,$I16,(INT($I16/100)*60+MOD($I16,100))/1440)) | S16: =IF(NOT(ISNUMBER($J16)),"",IF($J16<1,$J16,(INT($J16/100)*60+MOD($J16,100))/1440)) | T16: =IF(OR($N16="",$O16=""),"",MOD($O16-$N16,1)) | U16: =IF($A16="","",IF($K16<>"","祝",IF(WEEKDAY($A16,2)=6,"土",IF(WEEKDAY($A16,2)=7,"日","平"))))
A17: =IF(A16="","",IF(MONTH(A16+1)=$C$2,A16+1,"")) -> 46033 | B17: =IF(A17="","","日") | C17: =IF(A17="","","("&CHOOSE(WEEKDAY(A17,2),"月","火","水","木","金","土","日")&"）") -> (日） | E17: ～ | K17: =IF($A17="","",IFERROR(VLOOKUP($A17,祝日リスト!$A$2:$C$40,3,0),"")) | N17: =IF(NOT(ISNUMBER($D17)),"",IF($D17<1,$D17,(INT($D17/100)*60+MOD($D17,100))/1440)) | O17: =IF(NOT(ISNUMBER($F17)),"",IF($F17<1,$F17,(INT($F17/100)*60+MOD($F17,100))/1440)) | P17: =IF(NOT(ISNUMBER($G17)),"",IF($G17<1,$G17,(INT($G17/100)*60+MOD($G17,100))/1440)) | Q17: =IF(NOT(ISNUMBER($H17)),"",IF($H17<1,$H17,(INT($H17/100)*60+MOD($H17,100))/1440)) | R17: =IF(NOT(ISNUMBER($I17)),"",IF($I17<1,$I17,(INT($I17/100)*60+MOD($I17,100))/1440)) | S17: =IF(NOT(ISNUMBER($J17)),"",IF($J17<1,$J17,(INT($J17/100)*60+MOD($J17,100))/1440)) | T17: =IF(OR($N17="",$O17=""),"",MOD($O17-$N17,1)) | U17: =IF($A17="","",IF($K17<>"","祝",IF(WEEKDAY($A17,2)=6,"土",IF(WEEKDAY($A17,2)=7,"日","平"))))
A18: =IF(A17="","",IF(MONTH(A17+1)=$C$2,A17+1,"")) -> 46034 | B18: =IF(A18="","","日") | C18: =IF(A18="","","("&CHOOSE(WEEKDAY(A18,2),"月","火","水","木","金","土","日")&"）") -> (月） | E18: ～ | K18: =IF($A18="","",IFERROR(VLOOKUP($A18,祝日リスト!$A$2:$C$40,3,0),"")) -> 成人の日 | N18: =IF(NOT(ISNUMBER($D18)),"",IF($D18<1,$D18,(INT($D18/100)*60+MOD($D18,100))/1440)) | O18: =IF(NOT(ISNUMBER($F18)),"",IF($F18<1,$F18,(INT($F18/100)*60+MOD($F18,100))/1440)) | P18: =IF(NOT(ISNUMBER($G18)),"",IF($G18<1,$G18,(INT($G18/100)*60+MOD($G18,100))/1440)) | Q18: =IF(NOT(ISNUMBER($H18)),"",IF($H18<1,$H18,(INT($H18/100)*60+MOD($H18,100))/1440)) | R18: =IF(NOT(ISNUMBER($I18)),"",IF($I18<1,$I18,(INT($I18/100)*60+MOD($I18,100))/1440)) | S18: =IF(NOT(ISNUMBER($J18)),"",IF($J18<1,$J18,(INT($J18/100)*60+MOD($J18,100))/1440)) | T18: =IF(OR($N18="",$O18=""),"",MOD($O18-$N18,1)) | U18: =IF($A18="","",IF($K18<>"","祝",IF(WEEKDAY($A18,2)=6,"土",IF(WEEKDAY($A18,2)=7,"日","平"))))
A19: =IF(A18="","",IF(MONTH(A18+1)=$C$2,A18+1,"")) -> 46035 | B19: =IF(A19="","","日") | C19: =IF(A19="","","("&CHOOSE(WEEKDAY(A19,2),"月","火","水","木","金","土","日")&"）") -> (火） | E19: ～ | K19: =IF($A19="","",IFERROR(VLOOKUP($A19,祝日リスト!$A$2:$C$40,3,0),"")) | N19: =IF(NOT(ISNUMBER($D19)),"",IF($D19<1,$D19,(INT($D19/100)*60+MOD($D19,100))/1440)) | O19: =IF(NOT(ISNUMBER($F19)),"",IF($F19<1,$F19,(INT($F19/100)*60+MOD($F19,100))/1440)) | P19: =IF(NOT(ISNUMBER($G19)),"",IF($G19<1,$G19,(INT($G19/100)*60+MOD($G19,100))/1440)) | Q19: =IF(NOT(ISNUMBER($H19)),"",IF($H19<1,$H19,(INT($H19/100)*60+MOD($H19,100))/1440)) | R19: =IF(NOT(ISNUMBER($I19)),"",IF($I19<1,$I19,(INT($I19/100)*60+MOD($I19,100))/1440)) | S19: =IF(NOT(ISNUMBER($J19)),"",IF($J19<1,$J19,(INT($J19/100)*60+MOD($J19,100))/1440)) | T19: =IF(OR($N19="",$O19=""),"",MOD($O19-$N19,1)) | U19: =IF($A19="","",IF($K19<>"","祝",IF(WEEKDAY($A19,2)=6,"土",IF(WEEKDAY($A19,2)=7,"日","平"))))
... A37: =IF(A36="","",IF(MONTH(A36+1)=$C$2,A36+1,"")) -> 46053 | B37: =IF(A37="","","日") | C37: =IF(A37="","","("&CHOOSE(WEEKDAY(A37,2),"月","火","水","木","金","土","日")&"）") -> (土） | E37: ～ | K37: =IF($A37="","",IFERROR(VLOOKUP($A37,祝日リスト!$A$2:$C$40,3,0),"")) | N37: =IF(NOT(ISNUMBER($D37)),"",IF($D37<1,$D37,(INT($D37/100)*60+MOD($D37,100))/1440)) | O37: =IF(NOT(ISNUMBER($F37)),"",IF($F37<1,$F37,(INT($F37/100)*60+MOD($F37,100))/1440)) | P37: =IF(NOT(ISNUMBER($G37)),"",IF($G37<1,$G37,(INT($G37/100)*60+MOD($G37,100))/1440)) | Q37: =IF(NOT(ISNUMBER($H37)),"",IF($H37<1,$H37,(INT($H37/100)*60+MOD($H37,100))/1440)) | R37: =IF(NOT(ISNUMBER($I37)),"",IF($I37<1,$I37,(INT($I37/100)*60+MOD($I37,100))/1440)) | S37: =IF(NOT(ISNUMBER($J37)),"",IF($J37<1,$J37,(INT($J37/100)*60+MOD($J37,100))/1440)) | T37: =IF(OR($N37="",$O37=""),"",MOD($O37-$N37,1)) | U37: =IF($A37="","",IF($K37<>"","祝",IF(WEEKDAY($A37,2)=6,"土",IF(WEEKDAY($A37,2)=7,"日","平"))))
C39: 出勤日数 | D39: =COUNT($N$7:$N$37) -> 0 | F39: 日
C40: 普通出勤時間 | D40: =SUM($T$7:$T$37)-SUMIF($U$7:$U$37,"土",$T$7:$T$37) -> 0 | F40: 時間
C41: 残業 | D41: =SUM($P$7:$P$37)+SUM($Q$7:$Q$37)+SUM($R$7:$R$37) -> 0 | F41: 時間
C42: 土曜出勤 | D42: =SUMIF($U$7:$U$37,"土",$T$7:$T$37) -> 0 | F42: 時間 | I42: 合計 | J42: =SUM($T$7:$T$37) -> 0 | K42: 時間

Sheet 2月
A2: 2026 | B2: 年 | C2: 2 | D2: 月度出勤簿 | J2: 氏 名 | K2: 盛田 裕一
A6: 日付 | D6: 勤務時間 | G6: 通常残業 | H6: 深夜残業 | I6: 早朝残業 | J6: 遅刻・早退 | K6: 理由
A7: =DATE($A$2,$C$2,1) -> 46054 | B7: =IF(A7="","","日") | C7: =IF(A7="","","("&CHOOSE(WEEKDAY(A7,2),"月","火","水","木","金","土","日")&"）") -> (日） | E7: ～ | K7: =IF($A7="","",IFERROR(VLOOKUP($A7,祝日リスト!$A$2:$C$40,3,0),"")) | N7: =IF(NOT(ISNUMBER($D7)),"",IF($D7<1,$D7,(INT($D7/100)*60+MOD($D7,100))/1440)) | O7: =IF(NOT(ISNUMBER($F7)),"",IF($F7<1,$F7,(INT($F7/100)*60+MOD($F7,100))/1440)) | P7: =IF(NOT(ISNUMBER($G7)),"",IF($G7<1,$G7,(INT($G7/100)*60+MOD($G7,100))/1440)) | Q7: =IF(NOT(ISNUMBER($H7)),"",IF($H7<1,$H7,(INT($H7/100)*60+MOD($H7,100))/1440)) | R7: =IF(NOT(ISNUMBER($I7)),"",IF($I7<1,$I7,(INT($I7/100)*60+MOD($I7,100))/1440)) | S7: =IF(NOT(ISNUMBER($J7)),"",IF($J7<1,$J7,(INT($J7/100)*60+MOD($J7,100))/1440)) | T7: =IF(OR($N7="",$O7=""),"",MOD($O7-$N7,1)) | U7: =IF($A7="","",IF($K7<>"","祝",IF(WEEKDAY($A7,2)=6,"土",IF(WEEKDAY($A7,2)=7,"日","平"))))
A8: =IF(A7="","",IF(MONTH(A7+1)=$C$2,A7+1,"")) -> 46055 | B8: =IF(A8="","","日") | C8: =IF(A8="","","("&CHOOSE(WEEKDAY(A8,2),"月","火","水","木","金","土","日")&"）") -> (月） | E8: ～ | K8: =IF($A8="","",IFERROR(VLOOKUP($A8,祝日リスト!$A$2:$C$40,3,0),"")) | N8: =IF(NOT(ISNUMBER($D8)),"",IF($D8<1,$D8,(INT($D8/100)*60+MOD($D8,100))/1440)) | O8: =IF(NOT(ISNUMBER($F8)),"",IF($F8<1,$F8,(INT($F8/100)*60+MOD($F8,100))/1440)) | P8: =IF(NOT(ISNUMBER($G8)),"",IF($G8<1,$G8,(INT($G8/100)*60+MOD($G8,100))/1440)) | Q8: =IF(NOT(ISNUMBER($H8)),"",IF($H8<1,$H8,(INT($H8/100)*60+MOD($H8,100))/1440)) | R8: =IF(NOT(ISNUMBER($I8)),"",IF($I8<1,$I8,(INT($I8/100)*60+MOD($I8,100))/1440)) | S8: =IF(NOT(ISNUMBER($J8)),"",IF($J8<1,$J8,(INT($J8/100)*60+MOD($J8,100))/1440)) | T8: =IF(OR($N8="",$O8=""),"",MOD($O8-$N8,1)) | U8: =IF($A8="","",IF($K8<>"","祝",IF(WEEKDAY($A8,2)=6,"土",IF(WEEKDAY($A8,2)=7,"日","平"))))
A9: =IF(A8="","",IF(MONTH(A8+1)=$C$2,A8+1,"")) -> 46056 | B9: =IF(A9="","","日") | C9: =IF(A9="","","("&CHOOSE(WEEKDAY(A9,2),"月","火","水","木","金","土","日")&"）") -> (火） | E9: ～ | K9: =IF($A9="","",IFERROR(VLOOKUP($A9,祝日リスト!$A$2:$C$40,3,0),"")) | N9: =IF(NOT(ISNUMBER($D9)),"",IF($D9<1,$D9,(INT($D9/100)*60+MOD($D9,100))/1440)) | O9: =IF(NOT(ISNUMBER($F9)),"",IF($F9<1,$F9,(INT($F9/100)*60+MOD($F9,100))/1440)) | P9: =IF(NOT(ISNUMBER($G9)),"",IF($G9<1,$G9,(INT($G9/100)*60+MOD($G9,100))/1440)) | Q9: =IF(NOT(ISNUMBER($H9)),"",IF($H9<1,$H9,(INT($H9/100)*60+MOD($H9,100))/1440)) | R9: =IF(NOT(ISNUMBER($I9)),"",IF($I9<1,$I9,(INT($I9/100)*60+MOD($I9,100))/1440)) | S9: =IF(NOT(ISNUMBER($J9)),"",IF($J9<1,$J9,(INT($J9/100)*60+MOD($J9,100))/1440)) | T9: =IF(OR($N9="",$O9=""),"",MOD($O9-$N9,1)) | U9: =IF($A9="","",IF($K9<>"","祝",IF(WEEKDAY($A9,2)=6,"土",IF(WEEKDAY($A9,2)=7,"日","平"))))
A10: =IF(A9="","",IF(MONTH(A9+1)=$C$2,A9+1,"")) -> 46057 | B10: =IF(A10="","","日") | C10: =IF(A10="","","("&CHOOSE(WEEKDAY(A10,2),"月","火","水","木","金","土","日")&"）") -> (水） | E10: ～ | K10: =IF($A10="","",IFERROR(VLOOKUP($A10,祝日リスト!$A$2:$C$40,3,0),"")) | N10: =IF(NOT(ISNUMBER($D10)),"",IF($D10<1,$D10,(INT($D10/100)*60+MOD($D10,100))/1440)) | O10: =IF(NOT(ISNUMBER($F10)),"",IF($F10<1,$F10,(INT($F10/100)*60+MOD($F10,100))/1440)) | P10: =IF(NOT(ISNUMBER($G10)),"",IF($G10<1,$G10,(INT($G10/100)*60+MOD($G10,100))/1440)) | Q10: =IF(NOT(ISNUMBER($H10)),"",IF($H10<1,$H10,(INT($H10/100)*60+MOD($H10,100))/1440)) | R10: =IF(NOT(ISNUMBER($I10)),"",IF($I10<1,$I10,(INT($I10/100)*60+MOD($I10,100))/1440)) | S10: =IF(NOT(ISNUMBER($J10)),"",IF($J10<1,$J10,(INT($J10/100)*60+MOD($J10,100))/1440)) | T10: =IF(OR($N10="",$O10=""),"",MOD($O10-$N10,1)) | U10: =IF($A10="","",IF($K10<>"","祝",IF(WEEKDAY($A10,2)=6,"土",IF(WEEKDAY($A10,2)=7,"日","平"))))
A11: =IF(A10="","",IF(MONTH(A10+1)=$C$2,A10+1,"")) -> 46058 | B11: =IF(A11="","","日") | C11: =IF(A11="","","("&CHOOSE(WEEKDAY(A11,2),"月","火","水","木","金","土","日")&"）") -> (木） | E11: ～ | K11: =IF($A11="","",IFERROR(VLOOKUP($A11,祝日リスト!$A$2:$C$40,3,0),"")) | N11: =IF(NOT(ISNUMBER($D11)),"",IF($D11<1,$D11,(INT($D11/100)*60+MOD($D11,100))/1440)) | O11: =IF(NOT(ISNUMBER($F11)),"",IF($F11<1,$F11,(INT($F11/100)*60+MOD($F11,100))/1440)) | P11: =IF(NOT(ISNUMBER($G11)),"",IF($G11<1,$G11,(INT($G11/100)*60+MOD($G11,100))/1440)) | Q11: =IF(NOT(ISNUMBER($H11)),"",IF($H11<1,$H11,(INT($H11/100)*60+MOD($H11,100))/1440)) | R11: =IF(NOT(ISNUMBER($I11)),"",IF($I11<1,$I11,(INT($I11/100)*60+MOD($I11,100))/1440)) | S11: =IF(NOT(ISNUMBER($J11)),"",IF($J11<1,$J11,(INT($J11/100)*60+MOD($J11,100))/1440)) | T11: =IF(OR($N11="",$O11=""),"",MOD($O11-$N11,1)) | U11: =IF($A11="","",IF($K11<>"","祝",IF(WEEKDAY($A11,2)=6,"土",IF(WEEKDAY($A11,2)=7,"日","平"))))
A12: =IF(A11="","",IF(MONTH(A11+1)=$C$2,A11+1,"")) -> 46059 | B12: =IF(A12="","","日") | C12: =IF(A12="","","("&CHOOSE(WEEKDAY(A12,2),"月","火","水","木","金","土","日")&"）") -> (金） | E12: ～ | K12: =IF($A12="","",IFERROR(VLOOKUP($A12,祝日リスト!$A$2:$C$40,3,0),"")) | N12: =IF(NOT(ISNUMBER($D12)),"",IF($D12<1,$D12,(INT($D12/100)*60+MOD($D12,100))/1440)) | O12: =IF(NOT(ISNUMBER($F12)),"",IF($F12<1,$F12,(INT($F12/100)*60+MOD($F12,100))/1440)) | P12: =IF(NOT(ISNUMBER($G12)),"",IF($G12<1,$G12,(INT($G12/100)*60+MOD($G12,100))/1440)) | Q12: =IF(NOT(ISNUMBER($H12)),"",IF($H12<1,$H12,(INT($H12/100)*60+MOD($H12,100))/1440)) | R12: =IF(NOT(ISNUMBER($I12)),"",IF($I12<1,$I12,(INT($I12/100)*60+MOD($I12,100))/1440)) | S12: =IF(NOT(ISNUMBER($J12)),"",IF($J12<1,$J12,(INT($J12/100)*60+MOD($J12,100))/1440)) | T12: =IF(OR($N12="",$O12=""),"",MOD($O12-$N12,1)) | U12: =IF($A12="","",IF($K12<>"","祝",IF(WEEKDAY($A12,2)=6,"土",IF(WEEKDAY($A12,2)=7,"日","平"))))
A13: =IF(A12="","",IF(MONTH(A12+1)=$C$2,A12+1,"")) -> 46060 | B13: =IF(A13="","","日") | C13: =IF(A13="","","("&CHOOSE(WEEKDAY(A13,2),"月","火","水","木","金","土","日")&"）") -> (土） | E13: ～ | K13: =IF($A13="","",IFERROR(VLOOKUP($A13,祝日リスト!$A$2:$C$40,3,0),"")) | N13: =IF(NOT(ISNUMBER($D13)),"",IF($D13<1,$D13,(INT($D13/100)*60+MOD($D13,100))/1440)) | O13: =IF(NOT(ISNUMBER($F13)),"",IF($F13<1,$F13,(INT($F13/100)*60+MOD($F13,100))/1440)) | P13: =IF(NOT(ISNUMBER($G13)),"",IF($G13<1,$G13,(INT($G13/100)*60+MOD($G13,100))/1440)) | Q13: =IF(NOT(ISNUMBER($H13)),"",IF($H13<1,$H13,(INT($H13/100)*60+MOD($H13,100))/1440)) | R13: =IF(NOT(ISNUMBER($I13)),"",IF($I13<1,$I13,(INT($I13/100)*60+MOD($I13,100))/1440)) | S13: =IF(NOT(ISNUMBER($J13)),"",IF($J13<1,$J13,(INT($J13/100)*60+MOD($J13,100))/1440)) | T13: =IF(OR($N13="",$O13=""),"",MOD($O13-$N13,1)) | U13: =IF($A13="","",IF($K13<>"","祝",IF(WEEKDAY($A13,2)=6,"土",IF(WEEKDAY($A13,2)=7,"日","平"))))
A14: =IF(A13="","",IF(MONTH(A13+1)=$C$2,A13+1,"")) -> 46061 | B14: =IF(A14="","","日") | C14: =IF(A14="","","("&CHOOSE(WEEKDAY(A14,2),"月","火","水","木","金","土","日")&"）") -> (日） | E14: ～ | K14: =IF($A14="","",IFERROR(VLOOKUP($A14,祝日リスト!$A$2:$C$40,3,0),"")) | N14: =IF(NOT(ISNUMBER($D14)),"",IF($D14<1,$D14,(INT($D14/100)*60+MOD($D14,100))/1440)) | O14: =IF(NOT(ISNUMBER($F14)),"",IF($F14<1,$F14,(INT($F14/100)*60+MOD($F14,100))/1440)) | P14: =IF(NOT(ISNUMBER($G14)),"",IF($G14<1,$G14,(INT($G14/100)*60+MOD($G14,100))/1440)) | Q14: =IF(NOT(ISNUMBER($H14)),"",IF($H14<1,$H14,(INT($H14/100)*60+MOD($H14,100))/1440)) | R14: =IF(NOT(ISNUMBER($I14)),"",IF($I14<1,$I14,(INT($I14/100)*60+MOD($I14,100))/1440)) | S14: =IF(NOT(ISNUMBER($J14)),"",IF($J14<1,$J14,(INT($J14/100)*60+MOD($J14,100))/1440)) | T14: =IF(OR($N14="",$O14=""),"",MOD($O14-$N14,1)) | U14: =IF($A14="","",IF($K14<>"","祝",IF(WEEKDAY($A14,2)=6,"土",IF(WEEKDAY($A14,2)=7,"日","平"))))
A15: =IF(A14="","",IF(MONTH(A14+1)=$C$2,A14+1,"")) -> 46062 | B15: =IF(A15="","","日") | C15: =IF(A15="","","("&CHOOSE(WEEKDAY(A15,2),"月","火","水","木","金","土","日")&"）") -> (月） | E15: ～ | K15: =IF($A15="","",IFERROR(VLOOKUP($A15,祝日リスト!$A$2:$C$40,3,0),"")) | N15: =IF(NOT(ISNUMBER($D15)),"",IF($D15<1,$D15,(INT($D15/100)*60+MOD($D15,100))/1440)) | O15: =IF(NOT(ISNUMBER($F15)),"",IF($F15<1,$F15,(INT($F15/100)*60+MOD($F15,100))/1440)) | P15: =IF(NOT(ISNUMBER($G15)),"",IF($G15<1,$G15,(INT($G15/100)*60+MOD($G15,100))/1440)) | Q15: =IF(NOT(ISNUMBER($H15)),"",IF($H15<1,$H15,(INT($H15/100)*60+MOD($H15,100))/1440)) | R15: =IF(NOT(ISNUMBER($I15)),"",IF($I15<1,$I15,(INT($I15/100)*60+MOD($I15,100))/1440)) | S15: =IF(NOT(ISNUMBER($J15)),"",IF($J15<1,$J15,(INT($J15/100)*60+MOD($J15,100))/1440)) | T15: =IF(OR($N15="",$O15=""),"",MOD($O15-$N15,1)) | U15: =IF($A15="","",IF($K15<>"","祝",IF(WEEKDAY($A15,2)=6,"土",IF(WEEKDAY($A15,2)=7,"日","平"))))
A16: =IF(A15="","",IF(MONTH(A15+1)=$C$2,A15+1,"")) -> 46063 | B16: =IF(A16="","","日") | C16: =IF(A16="","","("&CHOOSE(WEEKDAY(A16,2),"月","火","水","木","金","土","日")&"）") -> (火） | E16: ～ | K16: =IF($A16="","",IFERROR(VLOOKUP($A16,祝日リスト!$A$2:$C$40,3,0),"")) | N16: =IF(NOT(ISNUMBER($D16)),"",IF($D16<1,$D16,(INT($D16/100)*60+MOD($D16,100))/1440)) | O16: =IF(NOT(ISNUMBER($F16)),"",IF($F16<1,$F16,(INT($F16/100)*60+MOD($F16,100))/1440)) | P16: =IF(NOT(ISNUMBER($G16)),"",IF($G16<1,$G16,(INT($G16/100)*60+MOD($G16,100))/1440)) | Q16: =IF(NOT(ISNUMBER($H16)),"",IF($H16<1,$H16,(INT($H16/100)*60+MOD($H16,100))/1440)) | R16: =IF(NOT(ISNUMBER($I16)),"",IF($I16<1,$I16,(INT($I16/100)*60+MOD($I16,100))/1440)) | S16: =IF(NOT(ISNUMBER($J16)),"",IF($J16<1,$J16,(INT($J16/100)*60+MOD($J16,100))/1440)) | T16: =IF(OR($N16="",$O16=""),"",MOD($O16-$N16,1)) | U16: =IF($A16="","",IF($K16<>"","祝",IF(WEEKDAY($A16,2)=6,"土",IF(WEEKDAY($A16,2)=7,"日","平"))))
A17: =IF(A16="","",IF(MONTH(A16+1)=$C$2,A16+1,"")) -> 46064 | B17: =IF(A17="","","日") | C17: =IF(A17="","","("&CHOOSE(WEEKDAY(A17,2),"月","火","水","木","金","土","日")&"）") -> (水） | E17: ～ | K17: =IF($A17="","",IFERROR(VLOOKUP($A17,祝日リスト!$A$2:$C$40,3,0),"")) -> 建国記念の日 | N17: =IF(NOT(ISNUMBER($D17)),"",IF($D17<1,$D17,(INT($D17/100)*60+MOD($D17,100))/1440)) | O17: =IF(NOT(ISNUMBER($F17)),"",IF($F17<1,$F17,(INT($F17/100)*60+MOD($F17,100))/1440)) | P17: =IF(NOT(ISNUMBER($G17)),"",IF($G17<1,$G17,(INT($G17/100)*60+MOD($G17,100))/1440)) | Q17: =IF(NOT(ISNUMBER($H17)),"",IF($H17<1,$H17,(INT($H17/100)*60+MOD($H17,100))/1440)) | R17: =IF(NOT(ISNUMBER($I17)),"",IF($I17<1,$I17,(INT($I17/100)*60+MOD($I17,100))/1440)) | S17: =IF(NOT(ISNUMBER($J17)),"",IF($J17<1,$J17,(INT($J17/100)*60+MOD($J17,100))/1440)) | T17: =IF(OR($N17="",$O17=""),"",MOD($O17-$N17,1)) | U17: =IF($A17="","",IF($K17<>"","祝",IF(WEEKDAY($A17,2)=6,"土",IF(WEEKDAY($A17,2)=7,"日","平"))))
A18: =IF(A17="","",IF(MONTH(A17+1)=$C$2,A17+1,"")) -> 46065 | B18: =IF(A18="","","日") | C18: =IF(A18="","","("&CHOOSE(WEEKDAY(A18,2),"月","火","水","木","金","土","日")&"）") -> (木） | E18: ～ | K18: =IF($A18="","",IFERROR(VLOOKUP($A18,祝日リスト!$A$2:$C$40,3,0),"")) | N18: =IF(NOT(ISNUMBER($D18)),"",IF($D18<1,$D18,(INT($D18/100)*60+MOD($D18,100))/1440)) | O18: =IF(NOT(ISNUMBER($F18)),"",IF($F18<1,$F18,(INT($F18/100)*60+MOD($F18,100))/1440)) | P18: =IF(NOT(ISNUMBER($G18)),"",IF($G18<1,$G18,(INT($G18/100)*60+MOD($G18,100))/1440)) | Q18: =IF(NOT(ISNUMBER($H18)),"",IF($H18<1,$H18,(INT($H18/100)*60+MOD($H18,100))/1440)) | R18: =IF(NOT(ISNUMBER($I18)),"",IF($I18<1,$I18,(INT($I18/100)*60+MOD($I18,100))/1440)) | S18: =IF(NOT(ISNUMBER($J18)),"",IF($J18<1,$J18,(INT($J18/100)*60+MOD($J18,100))/1440)) | T18: =IF(OR($N18="",$O18=""),"",MOD($O18-$N18,1)) | U18: =IF($A18="","",IF($K18<>"","祝",IF(WEEKDAY($A18,2)=6,"土",IF(WEEKDAY($A18,2)=7,"日","平"))))
A19: =IF(A18="","",IF(MONTH(A18+1)=$C$2,A18+1,"")) -> 46066 | B19: =IF(A19="","","日") | C19: =IF(A19="","","("&CHOOSE(WEEKDAY(A19,2),"月","火","水","木","金","土","日")&"）") -> (金） | E19: ～ | K19: =IF($A19="","",IFERROR(VLOOKUP($A19,祝日リスト!$A$2:$C$40,3,0),"")) | N19: =IF(NOT(ISNUMBER($D19)),"",IF($D19<1,$D19,(INT($D19/100)*60+MOD($D19,100))/1440)) | O19: =IF(NOT(ISNUMBER($F19)),"",IF($F19<1,$F19,(INT($F19/100)*60+MOD($F19,100))/1440)) | P19: =IF(NOT(ISNUMBER($G19)),"",IF($G19<1,$G19,(INT($G19/100)*60+MOD($G19,100))/1440)) | Q19: =IF(NOT(ISNUMBER($H19)),"",IF($H19<1,$H19,(INT($H19/100)*60+MOD($H19,100))/1440)) | R19: =IF(NOT(ISNUMBER($I19)),"",IF($I19<1,$I19,(INT($I19/100)*60+MOD($I19,100))/1440)) | S19: =IF(NOT(ISNUMBER($J19)),"",IF($J19<1,$J19,(INT($J19/100)*60+MOD($J19,100))/1440)) | T19: =IF(OR($N19="",$O19=""),"",MOD($O19-$N19,1)) | U19: =IF($A19="","",IF($K19<>"","祝",IF(WEEKDAY($A19,2)=6,"土",IF(WEEKDAY($A19,2)=7,"日","平"))))
... A37: =IF(A36="","",IF(MONTH(A36+1)=$C$2,A36+1,"")) | B37: =IF(A37="","","日") | C37: =IF(A37="","","("&CHOOSE(WEEKDAY(A37,2),"月","火","水","木","金","土","日")&"）") | E37: ～ | K37: =IF($A37="","",IFERROR(VLOOKUP($A37,祝日リスト!$A$2:$C$40,3,0),"")) | N37: =IF(NOT(ISNUMBER($D37)),"",IF($D37<1,$D37,(INT($D37/100)*60+MOD($D37,100))/1440)) | O37: =IF(NOT(ISNUMBER($F37)),"",IF($F37<1,$F37,(INT($F37/100)*60+MOD($F37,100))/1440)) | P37: =IF(NOT(ISNUMBER($G37)),"",IF($G37<1,$G37,(INT($G37/100)*60+MOD($G37,100))/1440)) | Q37: =IF(NOT(ISNUMBER($H37)),"",IF($H37<1,$H37,(INT($H37/100)*60+MOD($H37,100))/1440)) | R37: =IF(NOT(ISNUMBER($I37)),"",IF($I37<1,$I37,(INT($I37/100)*60+MOD($I37,100))/1440)) | S37: =IF(NOT(ISNUMBER($J37)),"",IF($J37<1,$J37,(INT($J37/100)*60+MOD($J37,100))/1440)) | T37: =IF(OR($N37="",$O37=""),"",MOD($O37-$N37,1)) | U37: =IF($A37="","",IF($K37<>"","祝",IF(WEEKDAY($A37,2)=6,"土",IF(WEEKDAY($A37,2)=7,"日","平"))))
C39: 出勤日数 | D39: =COUNT($N$7:$N$37) -> 0 | F39: 日
C40: 普通出勤時間 | D40: =SUM($T$7:$T$37)-SUMIF($U$7:$U$37,"土",$T$7:$T$37) -> 0 | F40: 時間
C41: 残業 | D41: =SUM($P$7:$P$37)+SUM($Q$7:$Q$37)+SUM($R$7:$R$37) -> 0 | F41: 時間
C42: 土曜出勤 | D42: =SUMIF($U$7:$U$37,"土",$T$7:$T$37) -> 0 | F42: 時間 | I42: 合計 | J42: =SUM($T$7:$T$37) -> 0 | K42: 時間

Sheet 3月
A2: 2026 | B2: 年 | C2: 3 | D2: 月度出勤簿 | J2: 氏 名 | K2: 盛田 裕一
A6: 日付 | D6: 勤務時間 | G6: 通常残業 | H6: 深夜残業 | I6: 早朝残業 | J6: 遅刻・早退 | K6: 理由
A7: =DATE($A$2,$C$2,1) -> 46082 | B7: =IF(A7="","","日") | C7: =IF(A7="","","("&CHOOSE(WEEKDAY(A7,2),"月","火","水","木","金","土","日")&"）") -> (日） | E7: ～ | K7: =IF($A7="","",IFERROR(VLOOKUP($A7,祝日リスト!$A$2:$C$40,3,0),"")) | N7: =IF(NOT(ISNUMBER($D7)),"",IF($D7<1,$D7,(INT($D7/100)*60+MOD($D7,100))/1440)) | O7: =IF(NOT(ISNUMBER($F7)),"",IF($F7<1,$F7,(INT($F7/100)*60+MOD($F7,100))/1440)) | P7: =IF(NOT(ISNUMBER($G7)),"",IF($G7<1,$G7,(INT($G7/100)*60+MOD($G7,100))/1440)) | Q7: =IF(NOT(ISNUMBER($H7)),"",IF($H7<1,$H7,(INT($H7/100)*60+MOD($H7,100))/1440)) | R7: =IF(NOT(ISNUMBER($I7)),"",IF($I7<1,$I7,(INT($I7/100)*60+MOD($I7,100))/1440)) | S7: =IF(NOT(ISNUMBER($J7)),"",IF($J7<1,$J7,(INT($J7/100)*60+MOD($J7,100))/1440)) | T7: =IF(OR($N7="",$O7=""),"",MOD($O7-$N7,1)) | U7: =IF($A7="","",IF($K7<>"","祝",IF(WEEKDAY($A7,2)=6,"土",IF(WEEKDAY($A7,2)=7,"日","平"))))
A8: =IF(A7="","",IF(MONTH(A7+1)=$C$2,A7+1,"")) -> 46083 | B8: =IF(A8="","","日") | C8: =IF(A8="","","("&CHOOSE(WEEKDAY(A8,2),"月","火","水","木","金","土","日")&"）") -> (月） | E8: ～ | K8: =IF($A8="","",IFERROR(VLOOKUP($A8,祝日リスト!$A$2:$C$40,3,0),"")) | N8: =IF(NOT(ISNUMBER($D8)),"",IF($D8<1,$D8,(INT($D8/100)*60+MOD($D8,100))/1440)) | O8: =IF(NOT(ISNUMBER($F8)),"",IF($F8<1,$F8,(INT($F8/100)*60+MOD($F8,100))/1440)) | P8: =IF(NOT(ISNUMBER($G8)),"",IF($G8<1,$G8,(INT($G8/100)*60+MOD($G8,100))/1440)) | Q8: =IF(NOT(ISNUMBER($H8)),"",IF($H8<1,$H8,(INT($H8/100)*60+MOD($H8,100))/1440)) | R8: =IF(NOT(ISNUMBER($I8)),"",IF($I8<1,$I8,(INT($I8/100)*60+MOD($I8,100))/1440)) | S8: =IF(NOT(ISNUMBER($J8)),"",IF($J8<1,$J8,(INT($J8/100)*60+MOD($J8,100))/1440)) | T8: =IF(OR($N8="",$O8=""),"",MOD($O8-$N8,1)) | U8: =IF($A8="","",IF($K8<>"","祝",IF(WEEKDAY($A8,2)=6,"土",IF(WEEKDAY($A8,2)=7,"日","平"))))
A9: =IF(A8="","",IF(MONTH(A8+1)=$C$2,A8+1,"")) -> 46084 | B9: =IF(A9="","","日") | C9: =IF(A9="","","("&CHOOSE(WEEKDAY(A9,2),"月","火","水","木","金","土","日")&"）") -> (火） | E9: ～ | K9: =IF($A9="","",IFERROR(VLOOKUP($A9,祝日リスト!$A$2:$C$40,3,0),"")) | N9: =IF(NOT(ISNUMBER($D9)),"",IF($D9<1,$D9,(INT($D9/100)*60+MOD($D9,100))/1440)) | O9: =IF(NOT(ISNUMBER($F9)),"",IF($F9<1,$F9,(INT($F9/100)*60+MOD($F9,100))/1440)) | P9: =IF(NOT(ISNUMBER($G9)),"",IF($G9<1,$G9,(INT($G9/100)*60+MOD($G9,100))/1440)) | Q9: =IF(NOT(ISNUMBER($H9)),"",IF($H9<1,$H9,(INT($H9/100)*60+MOD($H9,100))/1440)) | R9: =IF(NOT(ISNUMBER($I9)),"",IF($I9<1,$I9,(INT($I9/100)*60+MOD($I9,100))/1440)) | S9: =IF(NOT(ISNUMBER($J9)),"",IF($J9<1,$J9,(INT($J9/100)*60+MOD($J9,100))/1440)) | T9: =IF(OR($N9="",$O9=""),"",MOD($O9-$N9,1)) | U9: =IF($A9="","",IF($K9<>"","祝",IF(WEEKDAY($A9,2)=6,"土",IF(WEEKDAY($A9,2)=7,"日","平"))))
A10: =IF(A9="","",IF(MONTH(A9+1)=$C$2,A9+1,"")) -> 46085 | B10: =IF(A10="","","日") | C10: =IF(A10="","","("&CHOOSE(WEEKDAY(A10,2),"月","火","水","木","金","土","日")&"）") -> (水） | E10: ～ | K10: =IF($A10="","",IFERROR(VLOOKUP($A10,祝日リスト!$A$2:$C$40,3,0),"")) | N10: =IF(NOT(ISNUMBER($D10)),"",IF($D10<1,$D10,(INT($D10/100)*60+MOD($D10,100))/1440)) | O10: =IF(NOT(ISNUMBER($F10)),"",IF($F10<1,$F10,(INT($F10/100)*60+MOD($F10,100))/1440)) | P10: =IF(NOT(ISNUMBER($G10)),"",IF($G10<1,$G10,(INT($G10/100)*60+MOD($G10,100))/1440)) | Q10: =IF(NOT(ISNUMBER($H10)),"",IF($H10<1,$H10,(INT($H10/100)*60+MOD($H10,100))/1440)) | R10: =IF(NOT(ISNUMBER($I10)),"",IF($I10<1,$I10,(INT($I10/100)*60+MOD($I10,100))/1440)) | S10: =IF(NOT(ISNUMBER($J10)),"",IF($J10<1,$J10,(INT($J10/100)*60+MOD($J10,100))/1440)) | T10: =IF(OR($N10="",$O10=""),"",MOD($O10-$N10,1)) | U10: =IF($A10="","",IF($K10<>"","祝",IF(WEEKDAY($A10,2)=6,"土",IF(WEEKDAY($A10,2)=7,"日","平"))))
A11: =IF(A10="","",IF(MONTH(A10+1)=$C$2,A10+1,"")) -> 46086 | B11: =IF(A11="","","日") | C11: =IF(A11="","","("&CHOOSE(WEEKDAY(A11,2),"月","火","水","木","金","土","日")&"）") -> (木） | E11: ～ | K11: =IF($A11="","",IFERROR(VLOOKUP($A11,祝日リスト!$A$2:$C$40,3,0),"")) | N11: =IF(NOT(ISNUMBER($D11)),"",IF($D11<1,$D11,(INT($D11/100)*60+MOD($D11,100))/1440)) | O11: =IF(NOT(ISNUMBER($F11)),"",IF($F11<1,$F11,(INT($F11/100)*60+MOD($F11,100))/1440)) | P11: =IF(NOT(ISNUMBER($G11)),"",IF($G11<1,$G11,(INT($G11/100)*60+MOD($G11,100))/1440)) | Q11: =IF(NOT(ISNUMBER($H11)),"",IF($H11<1,$H11,(INT($H11/100)*60+MOD($H11,100))/1440)) | R11: =IF(NOT(ISNUMBER($I11)),"",IF($I11<1,$I11,(INT($I11/100)*60+MOD($I11,100))/1440)) | S11: =IF(NOT(ISNUMBER($J11)),"",IF($J11<1,$J11,(INT($J11/100)*60+MOD($J11,100))/1440)) | T11: =IF(OR($N11="",$O11=""),"",MOD($O11-$N11,1)) | U11: =IF($A11="","",IF($K11<>"","祝",IF(WEEKDAY($A11,2)=6,"土",IF(WEEKDAY($A11,2)=7,"日","平"))))
A12: =IF(A11="","",IF(MONTH(A11+1)=$C$2,A11+1,"")) -> 46087 | B12: =IF(A12="","","日") | C12: =IF(A12="","","("&CHOOSE(WEEKDAY(A12,2),"月","火","水","木","金","土","日")&"）") -> (金） | E12: ～ | K12: =IF($A12="","",IFERROR(VLOOKUP($A12,祝日リスト!$A$2:$C$40,3,0),"")) | N12: =IF(NOT(ISNUMBER($D12)),"",IF($D12<1,$D12,(INT($D12/100)*60+MOD($D12,100))/1440)) | O12: =IF(NOT(ISNUMBER($F12)),"",IF($F12<1,$F12,(INT($F12/100)*60+MOD($F12,100))/1440)) | P12: =IF(NOT(ISNUMBER($G12)),"",IF($G12<1,$G12,(INT($G12/100)*60+MOD($G12,100))/1440)) | Q12: =IF(NOT(ISNUMBER($H12)),"",IF($H12<1,$H12,(INT($H12/100)*60+MOD($H12,100))/1440)) | R12: =IF(NOT(ISNUMBER($I12)),"",IF($I12<1,$I12,(INT($I12/100)*60+MOD($I12,100))/1440)) | S12: =IF(NOT(ISNUMBER($J12)),"",IF($J12<1,$J12,(INT($J12/100)*60+MOD($J12,100))/1440)) | T12: =IF(OR($N12="",$O12=""),"",MOD($O12-$N12,1)) | U12: =IF($A12="","",IF($K12<>"","祝",IF(WEEKDAY($A12,2)=6,"土",IF(WEEKDAY($A12,2)=7,"日","平"))))
A13: =IF(A12="","",IF(MONTH(A12+1)=$C$2,A12+1,"")) -> 46088 | B13: =IF(A13="","","日") | C13: =IF(A13="","","("&CHOOSE(WEEKDAY(A13,2),"月","火","水","木","金","土","日")&"）") -> (土） | E13: ～ | K13: =IF($A13="","",IFERROR(VLOOKUP($A13,祝日リスト!$A$2:$C$40,3,0),"")) | N13: =IF(NOT(ISNUMBER($D13)),"",IF($D13<1,$D13,(INT($D13/100)*60+MOD($D13,100))/1440)) | O13: =IF(NOT(ISNUMBER($F13)),"",IF($F13<1,$F13,(INT($F13/100)*60+MOD($F13,100))/1440)) | P13: =IF(NOT(ISNUMBER($G13)),"",IF($G13<1,$G13,(INT($G13/100)*60+MOD($G13,100))/1440)) | Q13: =IF(NOT(ISNUMBER($H13)),"",IF($H13<1,$H13,(INT($H13/100)*60+MOD($H13,100))/1440)) | R13: =IF(NOT(ISNUMBER($I13)),"",IF($I13<1,$I13,(INT($I13/100)*60+MOD($I13,100))/1440)) | S13: =IF(NOT(ISNUMBER($J13)),"",IF($J13<1,$J13,(INT($J13/100)*60+MOD($J13,100))/1440)) | T13: =IF(OR($N13="",$O13=""),"",MOD($O13-$N13,1)) | U13: =IF($A13="","",IF($K13<>"","祝",IF(WEEKDAY($A13,2)=6,"土",IF(WEEKDAY($A13,2)=7,"日","平"))))
A14: =IF(A13="","",IF(MONTH(A13+1)=$C$2,A13+1,"")) -> 46089 | B14: =IF(A14="","","日") | C14: =IF(A14="","","("&CHOOSE(WEEKDAY(A14,2),"月","火","水","木","金","土","日")&"）") -> (日） | E14: ～ | K14: =IF($A14="","",IFERROR(VLOOKUP($A14,祝日リスト!$A$2:$C$40,3,0),"")) | N14: =IF(NOT(ISNUMBER($D14)),"",IF($D14<1,$D14,(INT($D14/100)*60+MOD($D14,100))/1440)) | O14: =IF(NOT(ISNUMBER($F14)),"",IF($F14<1,$F14,(INT($F14/100)*60+MOD($F14,100))/1440)) | P14: =IF(NOT(ISNUMBER($G14)),"",IF($G14<1,$G14,(INT($G14/100)*60+MOD($G14,100))/1440)) | Q14: =IF(NOT(ISNUMBER($H14)),"",IF($H14<1,$H14,(INT($H14/100)*60+MOD($H14,100))/1440)) | R14: =IF(NOT(ISNUMBER($I14)),"",IF($I14<1,$I14,(INT($I14/100)*60+MOD($I14,100))/1440)) | S14: =IF(NOT(ISNUMBER($J14)),"",IF($J14<1,$J14,(INT($J14/100)*60+MOD($J14,100))/1440)) | T14: =IF(OR($N14="",$O14=""),"",MOD($O14-$N14,1)) | U14: =IF($A14="","",IF($K14<>"","祝",IF(WEEKDAY($A14,2)=6,"土",IF(WEEKDAY($A14,2)=7,"日","平"))))
A15: =IF(A14="","",IF(MONTH(A14+1)=$C$2,A14+1,"")) -> 46090 | B15: =IF(A15="","","日") | C15: =IF(A15="","","("&CHOOSE(WEEKDAY(A15,2),"月","火","水","木","金","土","日")&"）") -> (月） | E15: ～ | K15: =IF($A15="","",IFERROR(VLOOKUP($A15,祝日リスト!$A$2:$C$40,3,0),"")) | N15: =IF(NOT(ISNUMBER($D15)),"",IF($D15<1,$D15,(INT($D15/100)*60+MOD($D15,100))/1440)) | O15: =IF(NOT(ISNUMBER($F15)),"",IF($F15<1,$F15,(INT($F15/100)*60+MOD($F15,100))/1440)) | P15: =IF(NOT(ISNUMBER($G15)),"",IF($G15<1,$G15,(INT($G15/100)*60+MOD($G15,100))/1440)) | Q15: =IF(NOT(ISNUMBER($H15)),"",IF($H15<1,$H15,(INT($H15/100)*60+MOD($H15,100))/1440)) | R15: =IF(NOT(ISNUMBER($I15)),"",IF($I15<1,$I15,(INT($I15/100)*60+MOD($I15,100))/1440)) | S15: =IF(NOT(ISNUMBER($J15)),"",IF($J15<1,$J15,(INT($J15/100)*60+MOD($J15,100))/1440)) | T15: =IF(OR($N15="",$O15=""),"",MOD($O15-$N15,1)) | U15: =IF($A15="","",IF($K15<>"","祝",IF(WEEKDAY($A15,2)=6,"土",IF(WEEKDAY($A15,2)=7,"日","平"))))
A16: =IF(A15="","",IF(MONTH(A15+1)=$C$2,A15+1,"")) -> 46091 | B16: =IF(A16="","","日") | C16: =IF(A16="","","("&CHOOSE(WEEKDAY(A16,2),"月","火","水","木","金","土","日")&"）") -> (火） | E16: ～ | K16: =IF($A16="","",IFERROR(VLOOKUP($A16,祝日リスト!$A$2:$C$40,3,0),"")) | N16: =IF(NOT(ISNUMBER($D16)),"",IF($D16<1,$D16,(INT($D16/100)*60+MOD($D16,100))/1440)) | O16: =IF(NOT(ISNUMBER($F16)),"",IF($F16<1,$F16,(INT($F16/100)*60+MOD($F16,100))/1440)) | P16: =IF(NOT(ISNUMBER($G16)),"",IF($G16<1,$G16,(INT($G16/100)*60+MOD($G16,100))/1440)) | Q16: =IF(NOT(ISNUMBER($H16)),"",IF($H16<1,$H16,(INT($H16/100)*60+MOD($H16,100))/1440)) | R16: =IF(NOT(ISNUMBER($I16)),"",IF($I16<1,$I16,(INT($I16/100)*60+MOD($I16,100))/1440)) | S16: =IF(NOT(ISNUMBER($J16)),"",IF($J16<1,$J16,(INT($J16/100)*60+MOD($J16,100))/1440)) | T16: =IF(OR($N16="",$O16=""),"",MOD($O16-$N16,1)) | U16: =IF($A16="","",IF($K16<>"","祝",IF(WEEKDAY($A16,2)=6,"土",IF(WEEKDAY($A16,2)=7,"日","平"))))
A17: =IF(A16="","",IF(MONTH(A16+1)=$C$2,A16+1,"")) -> 46092 | B17: =IF(A17="","","日") | C17: =IF(A17="","","("&CHOOSE(WEEKDAY(A17,2),"月","火","水","木","金","土","日")&"）") -> (水） | E17: ～ | K17: =IF($A17="","",IFERROR(VLOOKUP($A17,祝日リスト!$A$2:$C$40,3,0),"")) | N17: =IF(NOT(ISNUMBER($D17)),"",IF($D17<1,$D17,(INT($D17/100)*60+MOD($D17,100))/1440)) | O17: =IF(NOT(ISNUMBER($F17)),"",IF($F17<1,$F17,(INT($F17/100)*60+MOD($F17,100))/1440)) | P17: =IF(NOT(ISNUMBER($G17)),"",IF($G17<1,$G17,(INT($G17/100)*60+MOD($G17,100))/1440)) | Q17: =IF(NOT(ISNUMBER($H17)),"",IF($H17<1,$H17,(INT($H17/100)*60+MOD($H17,100))/1440)) | R17: =IF(NOT(ISNUMBER($I17)),"",IF($I17<1,$I17,(INT($I17/100)*60+MOD($I17,100))/1440)) | S17: =IF(NOT(ISNUMBER($J17)),"",IF($J17<1,$J17,(INT($J17/100)*60+MOD($J17,100))/1440)) | T17: =IF(OR($N17="",$O17=""),"",MOD($O17-$N17,1)) | U17: =IF($A17="","",IF($K17<>"","祝",IF(WEEKDAY($A17,2)=6,"土",IF(WEEKDAY($A17,2)=7,"日","平"))))
A18: =IF(A17="","",IF(MONTH(A17+1)=$C$2,A17+1,"")) -> 46093 | B18: =IF(A18="","","日") | C18: =IF(A18="","","("&CHOOSE(WEEKDAY(A18,2),"月","火","水","木","金","土","日")&"）") -> (木） | E18: ～ | K18: =IF($A18="","",IFERROR(VLOOKUP($A18,祝日リスト!$A$2:$C$40,3,0),"")) | N18: =IF(NOT(ISNUMBER($D18)),"",IF($D18<1,$D18,(INT($D18/100)*60+MOD($D18,100))/1440)) | O18: =IF(NOT(ISNUMBER($F18)),"",IF($F18<1,$F18,(INT($F18/100)*60+MOD($F18,100))/1440)) | P18: =IF(NOT(ISNUMBER($G18)),"",IF($G18<1,$G18,(INT($G18/100)*60+MOD($G18,100))/1440)) | Q18: =IF(NOT(ISNUMBER($H18)),"",IF($H18<1,$H18,(INT($H18/100)*60+MOD($H18,100))/1440)) | R18: =IF(NOT(ISNUMBER($I18)),"",IF($I18<1,$I18,(INT($I18/100)*60+MOD($I18,100))/1440)) | S18: =IF(NOT(ISNUMBER($J18)),"",IF($J18<1,$J18,(INT($J18/100)*60+MOD($J18,100))/1440)) | T18: =IF(OR($N18="",$O18=""),"",MOD($O18-$N18,1)) | U18: =IF($A18="","",IF($K18<>"","祝",IF(WEEKDAY($A18,2)=6,"土",IF(WEEKDAY($A18,2)=7,"日","平"))))
A19: =IF(A18="","",IF(MONTH(A18+1)=$C$2,A18+1,"")) -> 46094 | B19: =IF(A19="","","日") | C19: =IF(A19="","","("&CHOOSE(WEEKDAY(A19,2),"月","火","水","木","金","土","日")&"）") -> (金） | E19: ～ | K19: =IF($A19="","",IFERROR(VLOOKUP($A19,祝日リスト!$A$2:$C$40,3,0),"")) | N19: =IF(NOT(ISNUMBER($D19)),"",IF($D19<1,$D19,(INT($D19/100)*60+MOD($D19,100))/1440)) | O19: =IF(NOT(ISNUMBER($F19)),"",IF($F19<1,$F19,(INT($F19/100)*60+MOD($F19,100))/1440)) | P19: =IF(NOT(ISNUMBER($G19)),"",IF($G19<1,$G19,(INT($G19/100)*60+MOD($G19,100))/1440)) | Q19: =IF(NOT(ISNUMBER($H19)),"",IF($H19<1,$H19,(INT($H19/100)*60+MOD($H19,100))/1440)) | R19: =IF(NOT(ISNUMBER($I19)),"",IF($I19<1,$I19,(INT($I19/100)*60+MOD($I19,100))/1440)) | S19: =IF(NOT(ISNUMBER($J19)),"",IF($J19<1,$J19,(INT($J19/100)*60+MOD($J19,100))/1440)) | T19: =IF(OR($N19="",$O19=""),"",MOD($O19-$N19,1)) | U19: =IF($A19="","",IF($K19<>"","祝",IF(WEEKDAY($A19,2)=6,"土",IF(WEEKDAY($A19,2)=7,"日","平"))))
... A37: =IF(A36="","",IF(MONTH(A36+1)=$C$2,A36+1,"")) -> 46112 | B37: =IF(A37="","","日") | C37: =IF(A37="","","("&CHOOSE(WEEKDAY(A37,2),"月","火","水","木","金","土","日")&"）") -> (火） | E37: ～ | K37: =IF($A37="","",IFERROR(VLOOKUP($A37,祝日リスト!$A$2:$C$40,3,0),"")) | N37: =IF(NOT(ISNUMBER($D37)),"",IF($D37<1,$D37,(INT($D37/100)*60+MOD($D37,100))/1440)) | O37: =IF(NOT(ISNUMBER($F37)),"",IF($F37<1,$F37,(INT($F37/100)*60+MOD($F37,100))/1440)) | P37: =IF(NOT(ISNUMBER($G37)),"",IF($G37<1,$G37,(INT($G37/100)*60+MOD($G37,100))/1440)) | Q37: =IF(NOT(ISNUMBER($H37)),"",IF($H37<1,$H37,(INT($H37/100)*60+MOD($H37,100))/1440)) | R37: =IF(NOT(ISNUMBER($I37)),"",IF($I37<1,$I37,(INT($I37/100)*60+MOD($I37,100))/1440)) | S37: =IF(NOT(ISNUMBER($J37)),"",IF($J37<1,$J37,(INT($J37/100)*60+MOD($J37,100))/1440)) | T37: =IF(OR($N37="",$O37=""),"",MOD($O37-$N37,1)) | U37: =IF($A37="","",IF($K37<>"","祝",IF(WEEKDAY($A37,2)=6,"土",IF(WEEKDAY($A37,2)=7,"日","平"))))
C39: 出勤日数 | D39: =COUNT($N$7:$N$37) -> 0 | F39: 日
C40: 普通出勤時間 | D40: =SUM($T$7:$T$37)-SUMIF($U$7:$U$37,"土",$T$7:$T$37) -> 0 | F40: 時間
C41: 残業 | D41: =SUM($P$7:$P$37)+SUM($Q$7:$Q$37)+SUM($R$7:$R$37) -> 0 | F41: 時間
C42: 土曜出勤 | D42: =SUMIF($U$7:$U$37,"土",$T$7:$T$37) -> 0 | F42: 時間 | I42: 合計 | J42: =SUM($T$7:$T$37) -> 0 | K42: 時間

Sheet 4月
A2: 2026 | B2: 年 | C2: 4 | D2: 月度出勤簿 | J2: 氏 名 | K2: 盛田 裕一
A6: 日付 | D6: 勤務時間 | G6: 通常残業 | H6: 深夜残業 | I6: 早朝残業 | J6: 遅刻・早退 | K6: 理由
A7: =DATE($A$2,$C$2,1) -> 46113 | B7: =IF(A7="","","日") | C7: =IF(A7="","","("&CHOOSE(WEEKDAY(A7,2),"月","火","水","木","金","土","日")&"）") -> (水） | E7: ～ | K7: =IF($A7="","",IFERROR(VLOOKUP($A7,祝日リスト!$A$2:$C$40,3,0),"")) | N7: =IF(NOT(ISNUMBER($D7)),"",IF($D7<1,$D7,(INT($D7/100)*60+MOD($D7,100))/1440)) | O7: =IF(NOT(ISNUMBER($F7)),"",IF($F7<1,$F7,(INT($F7/100)*60+MOD($F7,100))/1440)) | P7: =IF(NOT(ISNUMBER($G7)),"",IF($G7<1,$G7,(INT($G7/100)*60+MOD($G7,100))/1440)) | Q7: =IF(NOT(ISNUMBER($H7)),"",IF($H7<1,$H7,(INT($H7/100)*60+MOD($H7,100))/1440)) | R7: =IF(NOT(ISNUMBER($I7)),"",IF($I7<1,$I7,(INT($I7/100)*60+MOD($I7,100))/1440)) | S7: =IF(NOT(ISNUMBER($J7)),"",IF($J7<1,$J7,(INT($J7/100)*60+MOD($J7,100))/1440)) | T7: =IF(OR($N7="",$O7=""),"",MOD($O7-$N7,1)) | U7: =IF($A7="","",IF($K7<>"","祝",IF(WEEKDAY($A7,2)=6,"土",IF(WEEKDAY($A7,2)=7,"日","平"))))
A8: =IF(A7="","",IF(MONTH(A7+1)=$C$2,A7+1,"")) -> 46114 | B8: =IF(A8="","","日") | C8: =IF(A8="","","("&CHOOSE(WEEKDAY(A8,2),"月","火","水","木","金","土","日")&"）") -> (木） | E8: ～ | K8: =IF($A8="","",IFERROR(VLOOKUP($A8,祝日リスト!$A$2:$C$40,3,0),"")) | N8: =IF(NOT(ISNUMBER($D8)),"",IF($D8<1,$D8,(INT($D8/100)*60+MOD($D8,100))/1440)) | O8: =IF(NOT(ISNUMBER($F8)),"",IF($F8<1,$F8,(INT($F8/100)*60+MOD($F8,100))/1440)) | P8: =IF(NOT(ISNUMBER($G8)),"",IF($G8<1,$G8,(INT($G8/100)*60+MOD($G8,100))/1440)) | Q8: =IF(NOT(ISNUMBER($H8)),"",IF($H8<1,$H8,(INT($H8/100)*60+MOD($H8,100))/1440)) | R8: =IF(NOT(ISNUMBER($I8)),"",IF($I8<1,$I8,(INT($I8/100)*60+MOD($I8,100))/1440)) | S8: =IF(NOT(ISNUMBER($J8)),"",IF($J8<1,$J8,(INT($J8/100)*60+MOD($J8,100))/1440)) | T8: =IF(OR($N8="",$O8=""),"",MOD($O8-$N8,1)) | U8: =IF($A8="","",IF($K8<>"","祝",IF(WEEKDAY($A8,2)=6,"土",IF(WEEKDAY($A8,2)=7,"日","平"))))
A9: =IF(A8="","",IF(MONTH(A8+1)=$C$2,A8+1,"")) -> 46115 | B9: =IF(A9="","","日") | C9: =IF(A9="","","("&CHOOSE(WEEKDAY(A9,2),"月","火","水","木","金","土","日")&"）") -> (金） | E9: ～ | K9: =IF($A9="","",IFERROR(VLOOKUP($A9,祝日リスト!$A$2:$C$40,3,0),"")) | N9: =IF(NOT(ISNUMBER($D9)),"",IF($D9<1,$D9,(INT($D9/100)*60+MOD($D9,100))/1440)) | O9: =IF(NOT(ISNUMBER($F9)),"",IF($F9<1,$F9,(INT($F9/100)*60+MOD($F9,100))/1440)) | P9: =IF(NOT(ISNUMBER($G9)),"",IF($G9<1,$G9,(INT($G9/100)*60+MOD($G9,100))/1440)) | Q9: =IF(NOT(ISNUMBER($H9)),"",IF($H9<1,$H9,(INT($H9/100)*60+MOD($H9,100))/1440)) | R9: =IF(NOT(ISNUMBER($I9)),"",IF($I9<1,$I9,(INT($I9/100)*60+MOD($I9,100))/1440)) | S9: =IF(NOT(ISNUMBER($J9)),"",IF($J9<1,$J9,(INT($J9/100)*60+MOD($J9,100))/1440)) | T9: =IF(OR($N9="",$O9=""),"",MOD($O9-$N9,1)) | U9: =IF($A9="","",IF($K9<>"","祝",IF(WEEKDAY($A9,2)=6,"土",IF(WEEKDAY($A9,2)=7,"日","平"))))
A10: =IF(A9="","",IF(MONTH(A9+1)=$C$2,A9+1,"")) -> 46116 | B10: =IF(A10="","","日") | C10: =IF(A10="","","("&CHOOSE(WEEKDAY(A10,2),"月","火","水","木","金","土","日")&"）") -> (土） | E10: ～ | K10: =IF($A10="","",IFERROR(VLOOKUP($A10,祝日リスト!$A$2:$C$40,3,0),"")) | N10: =IF(NOT(ISNUMBER($D10)),"",IF($D10<1,$D10,(INT($D10/100)*60+MOD($D10,100))/1440)) | O10: =IF(NOT(ISNUMBER($F10)),"",IF($F10<1,$F10,(INT($F10/100)*60+MOD($F10,100))/1440)) | P10: =IF(NOT(ISNUMBER($G10)),"",IF($G10<1,$G10,(INT($G10/100)*60+MOD($G10,100))/1440)) | Q10: =IF(NOT(ISNUMBER($H10)),"",IF($H10<1,$H10,(INT($H10/100)*60+MOD($H10,100))/1440)) | R10: =IF(NOT(ISNUMBER($I10)),"",IF($I10<1,$I10,(INT($I10/100)*60+MOD($I10,100))/1440)) | S10: =IF(NOT(ISNUMBER($J10)),"",IF($J10<1,$J10,(INT($J10/100)*60+MOD($J10,100))/1440)) | T10: =IF(OR($N10="",$O10=""),"",MOD($O10-$N10,1)) | U10: =IF($A10="","",IF($K10<>"","祝",IF(WEEKDAY($A10,2)=6,"土",IF(WEEKDAY($A10,2)=7,"日","平"))))
A11: =IF(A10="","",IF(MONTH(A10+1)=$C$2,A10+1,"")) -> 46117 | B11: =IF(A11="","","日") | C11: =IF(A11="","","("&CHOOSE(WEEKDAY(A11,2),"月","火","水","木","金","土","日")&"）") -> (日） | E11: ～ | K11: =IF($A11="","",IFERROR(VLOOKUP($A11,祝日リスト!$A$2:$C$40,3,0),"")) | N11: =IF(NOT(ISNUMBER($D11)),"",IF($D11<1,$D11,(INT($D11/100)*60+MOD($D11,100))/1440)) | O11: =IF(NOT(ISNUMBER($F11)),"",IF($F11<1,$F11,(INT($F11/100)*60+MOD($F11,100))/1440)) | P11: =IF(NOT(ISNUMBER($G11)),"",IF($G11<1,$G11,(INT($G11/100)*60+MOD($G11,100))/1440)) | Q11: =IF(NOT(ISNUMBER($H11)),"",IF($H11<1,$H11,(INT($H11/100)*60+MOD($H11,100))/1440)) | R11: =IF(NOT(ISNUMBER($I11)),"",IF($I11<1,$I11,(INT($I11/100)*60+MOD($I11,100))/1440)) | S11: =IF(NOT(ISNUMBER($J11)),"",IF($J11<1,$J11,(INT($J11/100)*60+MOD($J11,100))/1440)) | T11: =IF(OR($N11="",$O11=""),"",MOD($O11-$N11,1)) | U11: =IF($A11="","",IF($K11<>"","祝",IF(WEEKDAY($A11,2)=6,"土",IF(WEEKDAY($A11,2)=7,"日","平"))))
A12: =IF(A11="","",IF(MONTH(A11+1)=$C$2,A11+1,"")) -> 46118 | B12: =IF(A12="","","日") | C12: =IF(A12="","","("&CHOOSE(WEEKDAY(A12,2),"月","火","水","木","金","土","日")&"）") -> (月） | E12: ～ | K12: =IF($A12="","",IFERROR(VLOOKUP($A12,祝日リスト!$A$2:$C$40,3,0),"")) | N12: =IF(NOT(ISNUMBER($D12)),"",IF($D12<1,$D12,(INT($D12/100)*60+MOD($D12,100))/1440)) | O12: =IF(NOT(ISNUMBER($F12)),"",IF($F12<1,$F12,(INT($F12/100)*60+MOD($F12,100))/1440)) | P12: =IF(NOT(ISNUMBER($G12)),"",IF($G12<1,$G12,(INT($G12/100)*60+MOD($G12,100))/1440)) | Q12: =IF(NOT(ISNUMBER($H12)),"",IF($H12<1,$H12,(INT($H12/100)*60+MOD($H12,100))/1440)) | R12: =IF(NOT(ISNUMBER($I12)),"",IF($I12<1,$I12,(INT($I12/100)*60+MOD($I12,100))/1440)) | S12: =IF(NOT(ISNUMBER($J12)),"",IF($J12<1,$J12,(INT($J12/100)*60+MOD($J12,100))/1440)) | T12: =IF(OR($N12="",$O12=""),"",MOD($O12-$N12,1)) | U12: =IF($A12="","",IF($K12<>"","祝",IF(WEEKDAY($A12,2)=6,"土",IF(WEEKDAY($A12,2)=7,"日","平"))))
A13: =IF(A12="","",IF(MONTH(A12+1)=$C$2,A12+1,"")) -> 46119 | B13: =IF(A13="","","日") | C13: =IF(A13="","","("&CHOOSE(WEEKDAY(A13,2),"月","火","水","木","金","土","日")&"）") -> (火） | E13: ～ | K13: =IF($A13="","",IFERROR(VLOOKUP($A13,祝日リスト!$A$2:$C$40,3,0),"")) | N13: =IF(NOT(ISNUMBER($D13)),"",IF($D13<1,$D13,(INT($D13/100)*60+MOD($D13,100))/1440)) | O13: =IF(NOT(ISNUMBER($F13)),"",IF($F13<1,$F13,(INT($F13/100)*60+MOD($F13,100))/1440)) | P13: =IF(NOT(ISNUMBER($G13)),"",IF($G13<1,$G13,(INT($G13/100)*60+MOD($G13,100))/1440)) | Q13: =IF(NOT(ISNUMBER($H13)),"",IF($H13<1,$H13,(INT($H13/100)*60+MOD($H13,100))/1440)) | R13: =IF(NOT(ISNUMBER($I13)),"",IF($I13<1,$I13,(INT($I13/100)*60+MOD($I13,100))/1440)) | S13: =IF(NOT(ISNUMBER($J13)),"",IF($J13<1,$J13,(INT($J13/100)*60+MOD($J13,100))/1440)) | T13: =IF(OR($N13="",$O13=""),"",MOD($O13-$N13,1)) | U13: =IF($A13="","",IF($K13<>"","祝",IF(WEEKDAY($A13,2)=6,"土",IF(WEEKDAY($A13,2)=7,"日","平"))))
A14: =IF(A13="","",IF(MONTH(A13+1)=$C$2,A13+1,"")) -> 46120 | B14: =IF(A14="","","日") | C14: =IF(A14="","","("&CHOOSE(WEEKDAY(A14,2),"月","火","水","木","金","土","日")&"）") -> (水） | E14: ～ | K14: =IF($A14="","",IFERROR(VLOOKUP($A14,祝日リスト!$A$2:$C$40,3,0),"")) | N14: =IF(NOT(ISNUMBER($D14)),"",IF($D14<1,$D14,(INT($D14/100)*60+MOD($D14,100))/1440)) | O14: =IF(NOT(ISNUMBER($F14)),"",IF($F14<1,$F14,(INT($F14/100)*60+MOD($F14,100))/1440)) | P14: =IF(NOT(ISNUMBER($G14)),"",IF($G14<1,$G14,(INT($G14/100)*60+MOD($G14,100))/1440)) | Q14: =IF(NOT(ISNUMBER($H14)),"",IF($H14<1,$H14,(INT($H14/100)*60+MOD($H14,100))/1440)) | R14: =IF(NOT(ISNUMBER($I14)),"",IF($I14<1,$I14,(INT($I14/100)*60+MOD($I14,100))/1440)) | S14: =IF(NOT(ISNUMBER($J14)),"",IF($J14<1,$J14,(INT($J14/100)*60+MOD($J14,100))/1440)) | T14: =IF(OR($N14="",$O14=""),"",MOD($O14-$N14,1)) | U14: =IF($A14="","",IF($K14<>"","祝",IF(WEEKDAY($A14,2)=6,"土",IF(WEEKDAY($A14,2)=7,"日","平"))))
A15: =IF(A14="","",IF(MONTH(A14+1)=$C$2,A14+1,"")) -> 46121 | B15: =IF(A15="","","日") | C15: =IF(A15="","","("&CHOOSE(WEEKDAY(A15,2),"月","火","水","木","金","土","日")&"）") -> (木） | E15: ～ | K15: =IF($A15="","",IFERROR(VLOOKUP($A15,祝日リスト!$A$2:$C$40,3,0),"")) | N15: =IF(NOT(ISNUMBER($D15)),"",IF($D15<1,$D15,(INT($D15/100)*60+MOD($D15,100))/1440)) | O15: =IF(NOT(ISNUMBER($F15)),"",IF($F15<1,$F15,(INT($F15/100)*60+MOD($F15,100))/1440)) | P15: =IF(NOT(ISNUMBER($G15)),"",IF($G15<1,$G15,(INT($G15/100)*60+MOD($G15,100))/1440)) | Q15: =IF(NOT(ISNUMBER($H15)),"",IF($H15<1,$H15,(INT($H15/100)*60+MOD($H15,100))/1440)) | R15: =IF(NOT(ISNUMBER($I15)),"",IF($I15<1,$I15,(INT($I15/100)*60+MOD($I15,100))/1440)) | S15: =IF(NOT(ISNUMBER($J15)),"",IF($J15<1,$J15,(INT($J15/100)*60+MOD($J15,100))/1440)) | T15: =IF(OR($N15="",$O15=""),"",MOD($O15-$N15,1)) | U15: =IF($A15="","",IF($K15<>"","祝",IF(WEEKDAY($A15,2)=6,"土",IF(WEEKDAY($A15,2)=7,"日","平"))))
A16: =IF(A15="","",IF(MONTH(A15+1)=$C$2,A15+1,"")) -> 46122 | B16: =IF(A16="","","日") | C16: =IF(A16="","","("&CHOOSE(WEEKDAY(A16,2),"月","火","水","木","金","土","日")&"）") -> (金） | E16: ～ | K16: =IF($A16="","",IFERROR(VLOOKUP($A16,祝日リスト!$A$2:$C$40,3,0),"")) | N16: =IF(NOT(ISNUMBER($D16)),"",IF($D16<1,$D16,(INT($D16/100)*60+MOD($D16,100))/1440)) | O16: =IF(NOT(ISNUMBER($F16)),"",IF($F16<1,$F16,(INT($F16/100)*60+MOD($F16,100))/1440)) | P16: =IF(NOT(ISNUMBER($G16)),"",IF($G16<1,$G16,(INT($G16/100)*60+MOD($G16,100))/1440)) | Q16: =IF(NOT(ISNUMBER($H16)),"",IF($H16<1,$H16,(INT($H16/100)*60+MOD($H16,100))/1440)) | R16: =IF(NOT(ISNUMBER($I16)),"",IF($I16<1,$I16,(INT($I16/100)*60+MOD($I16,100))/1440)) | S16: =IF(NOT(ISNUMBER($J16)),"",IF($J16<1,$J16,(INT($J16/100)*60+MOD($J16,100))/1440)) | T16: =IF(OR($N16="",$O16=""),"",MOD($O16-$N16,1)) | U16: =IF($A16="","",IF($K16<>"","祝",IF(WEEKDAY($A16,2)=6,"土",IF(WEEKDAY($A16,2)=7,"日","平"))))
A17: =IF(A16="","",IF(MONTH(A16+1)=$C$2,A16+1,"")) -> 46123 | B17: =IF(A17="","","日") | C17: =IF(A17="","","("&CHOOSE(WEEKDAY(A17,2),"月","火","水","木","金","土","日")&"）") -> (土） | E17: ～ | K17: =IF($A17="","",IFERROR(VLOOKUP($A17,祝日リスト!$A$2:$C$40,3,0),"")) | N17: =IF(NOT(ISNUMBER($D17)),"",IF($D17<1,$D17,(INT($D17/100)*60+MOD($D17,100))/1440)) | O17: =IF(NOT(ISNUMBER($F17)),"",IF($F17<1,$F17,(INT($F17/100)*60+MOD($F17,100))/1440)) | P17: =IF(NOT(ISNUMBER($G17)),"",IF($G17<1,$G17,(INT($G17/100)*60+MOD($G17,100))/1440)) | Q17: =IF(NOT(ISNUMBER($H17)),"",IF($H17<1,$H17,(INT($H17/100)*60+MOD($H17,100))/1440)) | R17: =IF(NOT(ISNUMBER($I17)),"",IF($I17<1,$I17,(INT($I17/100)*60+MOD($I17,100))/1440)) | S17: =IF(NOT(ISNUMBER($J17)),"",IF($J17<1,$J17,(INT($J17/100)*60+MOD($J17,100))/1440)) | T17: =IF(OR($N17="",$O17=""),"",MOD($O17-$N17,1)) | U17: =IF($A17="","",IF($K17<>"","祝",IF(WEEKDAY($A17,2)=6,"土",IF(WEEKDAY($A17,2)=7,"日","平"))))
A18: =IF(A17="","",IF(MONTH(A17+1)=$C$2,A17+1,"")) -> 46124 | B18: =IF(A18="","","日") | C18: =IF(A18="","","("&CHOOSE(WEEKDAY(A18,2),"月","火","水","木","金","土","日")&"）") -> (日） | E18: ～ | K18: =IF($A18="","",IFERROR(VLOOKUP($A18,祝日リスト!$A$2:$C$40,3,0),"")) | N18: =IF(NOT(ISNUMBER($D18)),"",IF($D18<1,$D18,(INT($D18/100)*60+MOD($D18,100))/1440)) | O18: =IF(NOT(ISNUMBER($F18)),"",IF($F18<1,$F18,(INT($F18/100)*60+MOD($F18,100))/1440)) | P18: =IF(NOT(ISNUMBER($G18)),"",IF($G18<1,$G18,(INT($G18/100)*60+MOD($G18,100))/1440)) | Q18: =IF(NOT(ISNUMBER($H18)),"",IF($H18<1,$H18,(INT($H18/100)*60+MOD($H18,100))/1440)) | R18: =IF(NOT(ISNUMBER($I18)),"",IF($I18<1,$I18,(INT($I18/100)*60+MOD($I18,100))/1440)) | S18: =IF(NOT(ISNUMBER($J18)),"",IF($J18<1,$J18,(INT($J18/100)*60+MOD($J18,100))/1440)) | T18: =IF(OR($N18="",$O18=""),"",MOD($O18-$N18,1)) | U18: =IF($A18="","",IF($K18<>"","祝",IF(WEEKDAY($A18,2)=6,"土",IF(WEEKDAY($A18,2)=7,"日","平"))))
A19: =IF(A18="","",IF(MONTH(A18+1)=$C$2,A18+1,"")) -> 46125 | B19: =IF(A19="","","日") | C19: =IF(A19="","","("&CHOOSE(WEEKDAY(A19,2),"月","火","水","木","金","土","日")&"）") -> (月） | E19: ～ | K19: =IF($A19="","",IFERROR(VLOOKUP($A19,祝日リスト!$A$2:$C$40,3,0),"")) | N19: =IF(NOT(ISNUMBER($D19)),"",IF($D19<1,$D19,(INT($D19/100)*60+MOD($D19,100))/1440)) | O19: =IF(NOT(ISNUMBER($F19)),"",IF($F19<1,$F19,(INT($F19/100)*60+MOD($F19,100))/1440)) | P19: =IF(NOT(ISNUMBER($G19)),"",IF($G19<1,$G19,(INT($G19/100)*60+MOD($G19,100))/1440)) | Q19: =IF(NOT(ISNUMBER($H19)),"",IF($H19<1,$H19,(INT($H19/100)*60+MOD($H19,100))/1440)) | R19: =IF(NOT(ISNUMBER($I19)),"",IF($I19<1,$I19,(INT($I19/100)*60+MOD($I19,100))/1440)) | S19: =IF(NOT(ISNUMBER($J19)),"",IF($J19<1,$J19,(INT($J19/100)*60+MOD($J19,100))/1440)) | T19: =IF(OR($N19="",$O19=""),"",MOD($O19-$N19,1)) | U19: =IF($A19="","",IF($K19<>"","祝",IF(WEEKDAY($A19,2)=6,"土",IF(WEEKDAY($A19,2)=7,"日","平"))))
A20: =IF(A19="","",IF(MONTH(A19+1)=$C$2,A19+1,"")) -> 46126 | B20: =IF(A20="","","日") | C20: =IF(A20="","","("&CHOOSE(WEEKDAY(A20,2),"月","火","水","木","金","土","日")&"）") -> (火） | E20: ～ | K20: =IF($A20="","",IFERROR(VLOOKUP($A20,祝日リスト!$A$2:$C$40,3,0),"")) | N20: =IF(NOT(ISNUMBER($D20)),"",IF($D20<1,$D20,(INT($D20/100)*60+MOD($D20,100))/1440)) | O20: =IF(NOT(ISNUMBER($F20)),"",IF($F20<1,$F20,(INT($F20/100)*60+MOD($F20,100))/1440)) | P20: =IF(NOT(ISNUMBER($G20)),"",IF($G20<1,$G20,(INT($G20/100)*60+MOD($G20,100))/1440)) | Q20: =IF(NOT(ISNUMBER($H20)),"",IF($H20<1,$H20,(INT($H20/100)*60+MOD($H20,100))/1440)) | R20: =IF(NOT(ISNUMBER($I20)),"",IF($I20<1,$I20,(INT($I20/100)*60+MOD($I20,100))/1440)) | S20: =IF(NOT(ISNUMBER($J20)),"",IF($J20<1,$J20,(INT($J20/100)*60+MOD($J20,100))/1440)) | T20: =IF(OR($N20="",$O20=""),"",MOD($O20-$N20,1)) | U20: =IF($A20="","",IF($K20<>"","祝",IF(WEEKDAY($A20,2)=6,"土",IF(WEEKDAY($A20,2)=7,"日","平"))))
A21: =IF(A20="","",IF(MONTH(A20+1)=$C$2,A20+1,"")) -> 46127 | B21: =IF(A21="","","日") | C21: =IF(A21="","","("&CHOOSE(WEEKDAY(A21,2),"月","火","水","木","金","土","日")&"）") -> (水） | D21: 900 | E21: ～ | F21: 1500 | K21: 入社日 | N21: =IF(NOT(ISNUMBER($D21)),"",IF($D21<1,$D21,(INT($D21/100)*60+MOD($D21,100))/1440)) | O21: =IF(NOT(ISNUMBER($F21)),"",IF($F21<1,$F21,(INT($F21/100)*60+MOD($F21,100))/1440)) | P21: =IF(NOT(ISNUMBER($G21)),"",IF($G21<1,$G21,(INT($G21/100)*60+MOD($G21,100))/1440)) | Q21: =IF(NOT(ISNUMBER($H21)),"",IF($H21<1,$H21,(INT($H21/100)*60+MOD($H21,100))/1440)) | R21: =IF(NOT(ISNUMBER($I21)),"",IF($I21<1,$I21,(INT($I21/100)*60+MOD($I21,100))/1440)) | S21: =IF(NOT(ISNUMBER($J21)),"",IF($J21<1,$J21,(INT($J21/100)*60+MOD($J21,100))/1440)) | T21: =IF(OR($N21="",$O21=""),"",MOD($O21-$N21,1)) | U21: =IF($A21="","",IF($K21<>"","祝",IF(WEEKDAY($A21,2)=6,"土",IF(WEEKDAY($A21,2)=7,"日","平"))))
A22: =IF(A21="","",IF(MONTH(A21+1)=$C$2,A21+1,"")) -> 46128 | B22: =IF(A22="","","日") | C22: =IF(A22="","","("&CHOOSE(WEEKDAY(A22,2),"月","火","水","木","金","土","日")&"）") -> (木） | D22: 900 | E22: ～ | F22: 1500 | K22: =IF($A22="","",IFERROR(VLOOKUP($A22,祝日リスト!$A$2:$C$40,3,0),"")) | N22: =IF(NOT(ISNUMBER($D22)),"",IF($D22<1,$D22,(INT($D22/100)*60+MOD($D22,100))/1440)) | O22: =IF(NOT(ISNUMBER($F22)),"",IF($F22<1,$F22,(INT($F22/100)*60+MOD($F22,100))/1440)) | P22: =IF(NOT(ISNUMBER($G22)),"",IF($G22<1,$G22,(INT($G22/100)*60+MOD($G22,100))/1440)) | Q22: =IF(NOT(ISNUMBER($H22)),"",IF($H22<1,$H22,(INT($H22/100)*60+MOD($H22,100))/1440)) | R22: =IF(NOT(ISNUMBER($I22)),"",IF($I22<1,$I22,(INT($I22/100)*60+MOD($I22,100))/1440)) | S22: =IF(NOT(ISNUMBER($J22)),"",IF($J22<1,$J22,(INT($J22/100)*60+MOD($J22,100))/1440)) | T22: =IF(OR($N22="",$O22=""),"",MOD($O22-$N22,1)) | U22: =IF($A22="","",IF($K22<>"","祝",IF(WEEKDAY($A22,2)=6,"土",IF(WEEKDAY($A22,2)=7,"日","平"))))
A23: =IF(A22="","",IF(MONTH(A22+1)=$C$2,A22+1,"")) -> 46129 | B23: =IF(A23="","","日") | C23: =IF(A23="","","("&CHOOSE(WEEKDAY(A23,2),"月","火","水","木","金","土","日")&"）") -> (金） | D23: 900 | E23: ～ | F23: 1500 | K23: =IF($A23="","",IFERROR(VLOOKUP($A23,祝日リスト!$A$2:$C$40,3,0),"")) | N23: =IF(NOT(ISNUMBER($D23)),"",IF($D23<1,$D23,(INT($D23/100)*60+MOD($D23,100))/1440)) | O23: =IF(NOT(ISNUMBER($F23)),"",IF($F23<1,$F23,(INT($F23/100)*60+MOD($F23,100))/1440)) | P23: =IF(NOT(ISNUMBER($G23)),"",IF($G23<1,$G23,(INT($G23/100)*60+MOD($G23,100))/1440)) | Q23: =IF(NOT(ISNUMBER($H23)),"",IF($H23<1,$H23,(INT($H23/100)*60+MOD($H23,100))/1440)) | R23: =IF(NOT(ISNUMBER($I23)),"",IF($I23<1,$I23,(INT($I23/100)*60+MOD($I23,100))/1440)) | S23: =IF(NOT(ISNUMBER($J23)),"",IF($J23<1,$J23,(INT($J23/100)*60+MOD($J23,100))/1440)) | T23: =IF(OR($N23="",$O23=""),"",MOD($O23-$N23,1)) | U23: =IF($A23="","",IF($K23<>"","祝",IF(WEEKDAY($A23,2)=6,"土",IF(WEEKDAY($A23,2)=7,"日","平"))))
A24: =IF(A23="","",IF(MONTH(A23+1)=$C$2,A23+1,"")) -> 46130 | B24: =IF(A24="","","日") | C24: =IF(A24="","","("&CHOOSE(WEEKDAY(A24,2),"月","火","水","木","金","土","日")&"）") -> (土） | E24: ～ | K24: =IF($A24="","",IFERROR(VLOOKUP($A24,祝日リスト!$A$2:$C$40,3,0),"")) | N24: =IF(NOT(ISNUMBER($D24)),"",IF($D24<1,$D24,(INT($D24/100)*60+MOD($D24,100))/1440)) | O24: =IF(NOT(ISNUMBER($F24)),"",IF($F24<1,$F24,(INT($F24/100)*60+MOD($F24,100))/1440)) | P24: =IF(NOT(ISNUMBER($G24)),"",IF($G24<1,$G24,(INT($G24/100)*60+MOD($G24,100))/1440)) | Q24: =IF(NOT(ISNUMBER($H24)),"",IF($H24<1,$H24,(INT($H24/100)*60+MOD($H24,100))/1440)) | R24: =IF(NOT(ISNUMBER($I24)),"",IF($I24<1,$I24,(INT($I24/100)*60+MOD($I24,100))/1440)) | S24: =IF(NOT(ISNUMBER($J24)),"",IF($J24<1,$J24,(INT($J24/100)*60+MOD($J24,100))/1440)) | T24: =IF(OR($N24="",$O24=""),"",MOD($O24-$N24,1)) | U24: =IF($A24="","",IF($K24<>"","祝",IF(WEEKDAY($A24,2)=6,"土",IF(WEEKDAY($A24,2)=7,"日","平"))))
A25: =IF(A24="","",IF(MONTH(A24+1)=$C$2,A24+1,"")) -> 46131 | B25: =IF(A25="","","日") | C25: =IF(A25="","","("&CHOOSE(WEEKDAY(A25,2),"月","火","水","木","金","土","日")&"）") -> (日） | E25: ～ | K25: =IF($A25="","",IFERROR(VLOOKUP($A25,祝日リスト!$A$2:$C$40,3,0),"")) | N25: =IF(NOT(ISNUMBER($D25)),"",IF($D25<1,$D25,(INT($D25/100)*60+MOD($D25,100))/1440)) | O25: =IF(NOT(ISNUMBER($F25)),"",IF($F25<1,$F25,(INT($F25/100)*60+MOD($F25,100))/1440)) | P25: =IF(NOT(ISNUMBER($G25)),"",IF($G25<1,$G25,(INT($G25/100)*60+MOD($G25,100))/1440)) | Q25: =IF(NOT(ISNUMBER($H25)),"",IF($H25<1,$H25,(INT($H25/100)*60+MOD($H25,100))/1440)) | R25: =IF(NOT(ISNUMBER($I25)),"",IF($I25<1,$I25,(INT($I25/100)*60+MOD($I25,100))/1440)) | S25: =IF(NOT(ISNUMBER($J25)),"",IF($J25<1,$J25,(INT($J25/100)*60+MOD($J25,100))/1440)) | T25: =IF(OR($N25="",$O25=""),"",MOD($O25-$N25,1)) | U25: =IF($A25="","",IF($K25<>"","祝",IF(WEEKDAY($A25,2)=6,"土",IF(WEEKDAY($A25,2)=7,"日","平"))))
A26: =IF(A25="","",IF(MONTH(A25+1)=$C$2,A25+1,"")) -> 46132 | B26: =IF(A26="","","日") | C26: =IF(A26="","","("&CHOOSE(WEEKDAY(A26,2),"月","火","水","木","金","土","日")&"）") -> (月） | D26: 900 | E26: ～ | F26: 1500 | K26: =IF($A26="","",IFERROR(VLOOKUP($A26,祝日リスト!$A$2:$C$40,3,0),"")) | N26: =IF(NOT(ISNUMBER($D26)),"",IF($D26<1,$D26,(INT($D26/100)*60+MOD($D26,100))/1440)) | O26: =IF(NOT(ISNUMBER($F26)),"",IF($F26<1,$F26,(INT($F26/100)*60+MOD($F26,100))/1440)) | P26: =IF(NOT(ISNUMBER($G26)),"",IF($G26<1,$G26,(INT($G26/100)*60+MOD($G26,100))/1440)) | Q26: =IF(NOT(ISNUMBER($H26)),"",IF($H26<1,$H26,(INT($H26/100)*60+MOD($H26,100))/1440)) | R26: =IF(NOT(ISNUMBER($I26)),"",IF($I26<1,$I26,(INT($I26/100)*60+MOD($I26,100))/1440)) | S26: =IF(NOT(ISNUMBER($J26)),"",IF($J26<1,$J26,(INT($J26/100)*60+MOD($J26,100))/1440)) | T26: =IF(OR($N26="",$O26=""),"",MOD($O26-$N26,1)) | U26: =IF($A26="","",IF($K26<>"","祝",IF(WEEKDAY($A26,2)=6,"土",IF(WEEKDAY($A26,2)=7,"日","平"))))
A27: =IF(A26="","",IF(MONTH(A26+1)=$C$2,A26+1,"")) -> 46133 | B27: =IF(A27="","","日") | C27: =IF(A27="","","("&CHOOSE(WEEKDAY(A27,2),"月","火","水","木","金","土","日")&"）") -> (火） | D27: 900 | E27: ～ | F27: 1500 | K27: =IF($A27="","",IFERROR(VLOOKUP($A27,祝日リスト!$A$2:$C$40,3,0),"")) | N27: =IF(NOT(ISNUMBER($D27)),"",IF($D27<1,$D27,(INT($D27/100)*60+MOD($D27,100))/1440)) | O27: =IF(NOT(ISNUMBER($F27)),"",IF($F27<1,$F27,(INT($F27/100)*60+MOD($F27,100))/1440)) | P27: =IF(NOT(ISNUMBER($G27)),"",IF($G27<1,$G27,(INT($G27/100)*60+MOD($G27,100))/1440)) | Q27: =IF(NOT(ISNUMBER($H27)),"",IF($H27<1,$H27,(INT($H27/100)*60+MOD($H27,100))/1440)) | R27: =IF(NOT(ISNUMBER($I27)),"",IF($I27<1,$I27,(INT($I27/100)*60+MOD($I27,100))/1440)) | S27: =IF(NOT(ISNUMBER($J27)),"",IF($J27<1,$J27,(INT($J27/100)*60+MOD($J27,100))/1440)) | T27: =IF(OR($N27="",$O27=""),"",MOD($O27-$N27,1)) | U27: =IF($A27="","",IF($K27<>"","祝",IF(WEEKDAY($A27,2)=6,"土",IF(WEEKDAY($A27,2)=7,"日","平"))))
